Workbook

Sheet keycodes
A1: 日本語キー | B1: 英語キー | C1: キーコード | D1: 備考 | E1: キーコードエイリアス
A2: NOOP | B2: NOOP | C2: XXXXXXX
A3: Transparent | B3: Transparent | C3: _______
A4: A | B4: A | C4: KC_A
A5: B | B5: B | C5: KC_B
A6: C | B6: C | C6: KC_C
A7: D | B7: D | C7: KC_D
A8: E | B8: E | C8: KC_E
A9: F | B9: F | C9: KC_F
A10: G | B10: G | C10: KC_G
A11: H | B11: H | C11: KC_H
A12: I | B12: I | C12: KC_I
A13: J | B13: J | C13: KC_J
... A29: Z | B29: Z | C29: KC_Z
A30: 1 | B30: 1 | C30: KC_1
A31: 2 | B31: 2 | C31: KC_2
A32: 3 | B32: 3 | C32: KC_3
A33: 4 | B33: 4 | C33: KC_4
A34: 5 | B34: 5 | C34: KC_5
A35: 6 | B35: 6 | C35: KC_6
A36: 7 | B36: 7 | C36: KC_7
A37: 8 | B37: 8 | C37: KC_8
A38: 9 | B38: 9 | C38: KC_9
A39: 0 | B39: 0 | C39: KC_0
A40: F1 | B40: F1 | C40: KC_F1
A41: F2 | B41: F2 | C41: KC_F2
A42: F3 | B42: F3 | C42: KC_F3
A43: F4 | B43: F4 | C43: KC_F4
A44: F5 | B44: F5 | C44: KC_F5
A45: F6 | B45: F6 | C45: KC_F6
A46: F7 | B46: F7 | C46: KC_F7
A47: F8 | B47: F8 | C47: KC_F8
A48: F9 | B48: F9 | C48: KC_F9
A49: F10 | B49: F10 | C49: KC_F10
A50: F11 | B50: F11 | C50: KC_F11
A51: F12 | B51: F12 | C51: KC_F12
... A68: Left Alt | B68: Left Alt | C68: KC_LALT
A69: Left GUI | B69: Left GUI | C69: KC_LGUI | D69: Windows
A70: Right Control | B70: Right Control | C70: KC_RCTL
A71: Right Shift | B71: Right Shift | C71: KC_RSFT
...

Sheet YuhichYOC
B1: Japanese
A3: DEFAULT | B3: Esc | C3: Q | D3: W | E3: E | F3: R | G3: T | H3: NONE | I3: NONE | J3: Y | K3: U | L3: I | M3: O | N3: P | O3: @
B4: Tab | C4: A | D4: S | E4: D | F4: F | G4: G | H4: NONE | I4: NONE | J4: H | K4: J | L4: K | M4: L | N4: ; | O4: :
B5: Left Control | C5: Z | D5: X | E5: C | F5: V | G5: B | H5: NONE | I5: NONE | J5: N | K5: M | L5: , | M5: . | N5: / | O5: \
B6: NONE | C6: NONE | D6: NONE | E6: NONE | F6: ToggleRaise | G6: MoRaise | H6: Shift & Space | I6: Shift & Enter | J6: MoLower | K6: ToggleLower | L6: TERM | M6: TERM | N6: TERM | O6: TERM
A7: LOWER | B7: APP | C7: S ! | D7: S " | E7: S # | F7: S $ | G7: S % | H7: NONE | I7: NONE | J7: S & | K7: S ' | L7: S ( | M7: S ) | O7: S `
B8: Left GUI | D8: Home | E8: Page Up | F8: Page Down | G8: End | H8: NONE | I8: NONE | J8: Left Arrow | K8: Down Arrow | L8: Up Arrow | M8: Right Arrow | N8: ^ | O8: -
B9: Transparent | C9: Left Alt | F9: 無変換 | G9: Backspace | H9: NONE | I9: NONE | J9: Delete | K9: 変換 | L9: [ | M9: ] | N9: S Tilde | O9: S |
B10: NONE | C10: NONE | D10: NONE | E10: NONE | F10: Transparent | G10: Transparent | H10: Transparent | I10: Transparent | J10: Transparent | K10: Transparent | L10: TERM | M10: TERM | N10: TERM | O10: TERM
A11: RAISE | B11: F1 | C11: F2 | D11: F3 | E11: F4 | F11: F5 | G11: F6 | H11: NONE | I11: NONE | J11: F7 | K11: F8 | L11: F9 | M11: F10 | N11: F11 | O11: F12
B12: 半角/全角 | C12: 1 | D12: 2 | E12: 3 | F12: 4 | G12: 5 | H12: NONE | I12: NONE | J12: 6 | K12: 7 | L12: 8 | M12: 9 | N12: 0 | O12: Transparent
B13: Transparent | C13: Transparent | D13: Wheel Left | E13: Wheel Right | F13: Transparent | G13: Transparent | H13: NONE | I13: NONE | J13: Transparent | K13: Transparent | L13: , | M13: . | N13: / | O13: \
B14: NONE | C14: NONE | D14: NONE | E14: NONE | F14: Transparent | G14: Transparent | H14: Transparent | I14: Transparent | J14: Transparent | K14: Transparent | L14: TERM | M14: TERM | N14: TERM | O14: TERM
A15: ADJUST | B15: Esc | C15: Q | D15: W | E15: E | F15: R | G15: T | H15: NONE | I15: NONE | J15: Y | K15: U | L15: I | M15: O | N15: P | O15: @
B16: Tab | C16: A | D16: S | E16: D | F16: F | G16: G | H16: NONE | I16: NONE | J16: H | K16: J | L16: K | M16: L | N16: ; | O16: :
B17: Transparent | C17: Z | D17: X | E17: C | F17: V | G17: B | H17: NONE | I17: NONE | J17: N | K17: M | L17: Transparent | M17: Transparent | N17: Transparent | O17: Transparent
B18: NONE | C18: NONE | D18: NONE | E18: NONE | F18: ToggleRaise | G18: Space | H18: MoRaiseAdjust | I18: MoLowerAdjust | J18: Enter | K18: ToggleLower | L18: TERM | M18: TERM | N18: TERM | O18: TERM
A19: LOWER_ADJUST | C19: S ! | D19: S " | E19: S # | F19: S $ | G19: S % | H19: NONE | I19: NONE | J19: S & | K19: S ' | L19: S ( | M19: S ) | O19: S `
D20: Home | E20: Page Up | F20: Page Down | G20: End | H20: NONE | I20: NONE | J20: Left Arrow | K20: Down Arrow | L20: Up Arrow | M20: Right Arrow | N20: ^ | O20: -
B21: Transparent | C21: Left Alt | F21: 無変換 | G21: Backspace | H21: NONE | I21: NONE | J21: Delete | K21: 変換 | L21: [ | M21: ] | N21: S Tilde | O21: S |
B22: NONE | C22: NONE | D22: NONE | E22: NONE | F22: Transparent | G22: Transparent | H22: Transparent | I22: Transparent | J22: Transparent | K22: Transparent | L22: TERM | M22: TERM | N22: TERM | O22: TERM
A23: RAISE_ADJUST | B23: F1 | C23: F2 | D23: F3 | E23: F4 | F23: F5 | G23: F6 | H23: NONE | I23: NONE | J23: F7 | K23: F8 | L23: F9 | M23: F10 | N23: F11 | O23: F12
C24: 1 | D24: 2 | E24: 3 | F24: 4 | G24: 5 | H24: NONE | I24: NONE | J24: 6 | K24: 7 | L24: 8 | M24: 9 | N24: 0 | O24: Transparent
B25: Transparent | C25: Transparent | D25: Volume Down | E25: Volume Up | F25: Transparent | G25: Transparent | H25: NONE | I25: NONE | J25: Transparent | K25: Transparent | L25: , | M25: . | N25: / | O25: \
B26: NONE | C26: NONE | D26: NONE | E26: NONE | F26: Transparent | G26: Transparent | H26: Transparent | I26: Transparent | J26: Transparent | K26: Transparent | L26: TERM | M26: TERM | N26: TERM | O26: TERM
A29: DEFAULT | B29: =IF(B3="",keycodes!$C$2,IF($B$1="Japanese",IF(INDEX(keycodes!$E:$E,MATCH(B3,keycodes!$A:$A,0),0)<>"",INDEX(keycodes!$E:$E,MATCH(B3,keycodes!$A:$A,0),0),INDEX(keycodes!$C:$C,MATCH(B3,keycodes!$A:$A,0),0)),INDEX(keycodes!$C:$C,MATCH(B3,keycodes!$B:$B,0),0))) -> KC_ESC | C29: =IF(C3="",keycodes!$C$2,IF($B$1="Japanese",IF(INDEX(keycodes!$E:$E,MATCH(C3,keycodes!$A:$A,0),0)<>"",INDEX(keycodes!$E:$E,MATCH(C3,keycodes!$A:$A,0),0),INDEX(keycodes!$C:$C,MATCH(C3,keycodes!$A:$A,0),0)),INDEX(keycodes!$C:$C,MATCH(C3,keycodes!$B:$B,0),0))) -> KC_Q | D29: =IF(D3="",keycodes!$C$2,IF($B$1="Japanese",IF(INDEX(keycodes!$E:$E,MATCH(D3,keycodes!$A:$A,0),0)<>"",INDEX(keycodes!$E:$E,MATCH(D3,keycodes!$A:$A,0),0),INDEX(keycodes!$C:$C,MATCH(D3,keycodes!$A:$A,0),0)),INDEX(keycodes!$C:$C,MATCH(D3,keycodes!$B:$B,0),0))) -> KC_W | E29: =IF(E3="",keycodes!$C$2,IF($B$1="Japanese",IF(INDEX(keycodes!$E:$E,MATCH(E3,keycodes!$A:$A,0),0)<>"",INDEX(keycodes!$E:$E,MATCH(E3,keycodes!$A:$A,0),0),INDEX(keycodes!$C:$C,MATCH(E3,keycodes!$A:$A,0),0)),INDEX(keycodes!$C:$C,MATCH(E3,keycodes!$B:$B,0),0))) -> KC_E | F29: =IF(F3="",keycodes!$C$2,IF($B$1="Japanese",IF(INDEX(keycodes!$E:$E,MATCH(F3,keycodes!$A:$A,0),0)<>"",INDEX(keycodes!$E:$E,MATCH(F3,keycodes!$A:$A,0),0),INDEX(keycodes!$C:$C,MATCH(F3,keycodes!$A:$A,0),0)),INDEX(keycodes!$C:$C,MATCH(F3,keycodes!$B:$B,0),0))) -> KC_R | G29: =IF(G3="",keycodes!$C$2,IF($B$1="Japanese",IF(INDEX(keycodes!$E:$E,MATCH(G3,keycodes!$A:$A,0),0)<>"",INDEX(keycodes!$E:$E,MATCH(G3,keycodes!$A:$A,0),0),INDEX(keycodes!$C:$C,MATCH(G3,keycodes!$A:$A,0),0)),INDEX(keycodes!$C:$C,MATCH(G3,keycodes!$B:$B,0),0))) -> KC_T | H29: =IF(H3="",keycodes!$C$2,IF($B$1="Japanese",IF(INDEX(keycodes!$E:$E,MATCH(H3,keycodes!$A:$A,0),0)<>"",INDEX(keycodes!$E:$E,MATCH(H3,keycodes!$A:$A,0),0),INDEX(keycodes!$C:$C,MATCH(H3,keycodes!$A:$A,0),0)),INDEX(keycodes!$C:$C,MATCH(H3,keycodes!$B:$B,0),0))) -> NONE | I29: =IF(I3="",keycodes!$C$2,IF($B$1="Japanese",IF(INDEX(keycodes!$E:$E,MATCH(I3,keycodes!$A:$A,0),0)<>"",INDEX(keycodes!$E:$E,MATCH(I3,keycodes!$A:$A,0),0),INDEX(keycodes!$C:$C,MATCH(I3,keycodes!$A:$A,0),0)),INDEX(keycodes!$C:$C,MATCH(I3,keycodes!$B:$B,0),0))) -> NONE | ... O29: =IF(O3="",keycodes!$C$2,IF($B$1="Japanese",IF(INDEX(keycodes!$E:$E,MATCH(O3,keycodes!$A:$A,0),0)<>"",INDEX(keycodes!$E:$E,MATCH(O3,keycodes!$A:$A,0),0),INDEX(keycodes!$C:$C,MATCH(O3,keycodes!$A:$A,0),0)),INDEX(keycodes!$C:$C,MATCH(O3,keycodes!$B:$B,0),0))) -> KC_LBRC
B30: =IF(B4="",keycodes!$C$2,IF($B$1="Japanese",IF(INDEX(keycodes!$E:$E,MATCH(B4,keycodes!$A:$A,0),0)<>"",INDEX(keycodes!$E:$E,MATCH(B4,keycodes!$A:$A,0),0),INDEX(keycodes!$C:$C,MATCH(B4,keycodes!$A:$A,0),0)),INDEX(keycodes!$C:$C,MATCH(B4,keycodes!$B:$B,0),0))) -> KC_TAB | C30: =IF(C4="",keycodes!$C$2,IF($B$1="Japanese",IF(INDEX(keycodes!$E:$E,MATCH(C4,keycodes!$A:$A,0),0)<>"",INDEX(keycodes!$E:$E,MATCH(C4,keycodes!$A:$A,0),0),INDEX(keycodes!$C:$C,MATCH(C4,keycodes!$A:$A,0),0)),INDEX(keycodes!$C:$C,MATCH(C4,keycodes!$B:$B,0),0))) -> KC_A | D30: =IF(D4="",keycodes!$C$2,IF($B$1="Japanese",IF(INDEX(keycodes!$E:$E,MATCH(D4,keycodes!$A:$A,0),0)<>"",INDEX(keycodes!$E:$E,MATCH(D4,keycodes!$A:$A,0),0),INDEX(keycodes!$C:$C,MATCH(D4,keycodes!$A:$A,0),0)),INDEX(keycodes!$C:$C,MATCH(D4,keycodes!$B:$B,0),0))) -> KC_S | E30: =IF(E4="",keycodes!$C$2,IF($B$1="Japanese",IF(INDEX(keycodes!$E:$E,MATCH(E4,keycodes!$A:$A,0),0)<>"",INDEX(keycodes!$E:$E,MATCH(E4,keycodes!$A:$A,0),0),INDEX(keycodes!$C:$C,MATCH(E4,keycodes!$A:$A,0),0)),INDEX(keycodes!$C:$C,MATCH(E4,keycodes!$B:$B,0),0))) -> KC_D | F30: =IF(F4="",keycodes!$C$2,IF($B$1="Japanese",IF(INDEX(keycodes!$E:$E,MATCH(F4,keycodes!$A:$A,0),0)<>"",INDEX(keycodes!$E:$E,MATCH(F4,keycodes!$A:$A,0),0),INDEX(keycodes!$C:$C,MATCH(F4,keycodes!$A:$A,0),0)),INDEX(keycodes!$C:$C,MATCH(F4,keycodes!$B:$B,0),0))) -> KC_F | G30: =IF(G4="",keycodes!$C$2,IF($B$1="Japanese",IF(INDEX(keycodes!$E:$E,MATCH(G4,keycodes!$A:$A,0),0)<>"",INDEX(keycodes!$E:$E,MATCH(G4,keycodes!$A:$A,0),0),INDEX(keycodes!$C:$C,MATCH(G4,keycodes!$A:$A,0),0)),INDEX(keycodes!$C:$C,MATCH(G4,keycodes!$B:$B,0),0))) -> KC_G | H30: =IF(H4="",keycodes!$C$2,IF($B$1="Japanese",IF(INDEX(keycodes!$E:$E,MATCH(H4,keycodes!$A:$A,0),0)<>"",INDEX(keycodes!$E:$E,MATCH(H4,keycodes!$A:$A,0),0),INDEX(keycodes!$C:$C,MATCH(H4,keycodes!$A:$A,0),0)),INDEX(keycodes!$C:$C,MATCH(H4,keycodes!$B:$B,0),0))) -> NONE | I30: =IF(I4="",keycodes!$C$2,IF($B$1="Japanese",IF(INDEX(keycodes!$E:$E,MATCH(I4,keycodes!$A:$A,0),0)<>"",INDEX(keycodes!$E:$E,MATCH(I4,keycodes!$A:$A,0),0),INDEX(keycodes!$C:$C,MATCH(I4,keycodes!$A:$A,0),0)),INDEX(keycodes!$C:$C,MATCH(I4,keycodes!$B:$B,0),0))) -> NONE | ... O30: =IF(O4="",keycodes!$C$2,IF($B$1="Japanese",IF(INDEX(keycodes!$E:$E,MATCH(O4,keycodes!$A:$A,0),0)<>"",INDEX(keycodes!$E:$E,MATCH(O4,keycodes!$A:$A,0),0),INDEX(keycodes!$C:$C,MATCH(O4,keycodes!$A:$A,0),0)),INDEX(keycodes!$C:$C,MATCH(O4,keycodes!$B:$B,0),0))) -> KC_QUOT
B31: =IF(B5="",keycodes!$C$2,IF($B$1="Japanese",IF(INDEX(keycodes!$E:$E,MATCH(B5,keycodes!$A:$A,0),0)<>"",INDEX(keycodes!$E:$E,MATCH(B5,keycodes!$A:$A,0),0),INDEX(keycodes!$C:$C,MATCH(B5,keycodes!$A:$A,0),0)),INDEX(keycodes!$C:$C,MATCH(B5,keycodes!$B:$B,0),0))) -> KC_LCTL | C31: =IF(C5="",keycodes!$C$2,IF($B$1="Japanese",IF(INDEX(keycodes!$E:$E,MATCH(C5,keycodes!$A:$A,0),0)<>"",INDEX(keycodes!$E:$E,MATCH(C5,keycodes!$A:$A,0),0),INDEX(keycodes!$C:$C,MATCH(C5,keycodes!$A:$A,0),0)),INDEX(keycodes!$C:$C,MATCH(C5,keycodes!$B:$B,0),0))) -> KC_Z | D31: =IF(D5="",keycodes!$C$2,IF($B$1="Japanese",IF(INDEX(keycodes!$E:$E,MATCH(D5,keycodes!$A:$A,0),0)<>"",INDEX(keycodes!$E:$E,MATCH(D5,keycodes!$A:$A,0),0),INDEX(keycodes!$C:$C,MATCH(D5,keycodes!$A:$A,0),0)),INDEX(keycodes!$C:$C,MATCH(D5,keycodes!$B:$B,0),0))) -> KC_X | E31: =IF(E5="",keycodes!$C$2,IF($B$1="Japanese",IF(INDEX(keycodes!$E:$E,MATCH(E5,keycodes!$A:$A,0),0)<>"",INDEX(keycodes!$E:$E,MATCH(E5,keycodes!$A:$A,0),0),INDEX(keycodes!$C:$C,MATCH(E5,keycodes!$A:$A,0),0)),INDEX(keycodes!$C:$C,MATCH(E5,keycodes!$B:$B,0),0))) -> KC_C | F31: =IF(F5="",keycodes!$C$2,IF($B$1="Japanese",IF(INDEX(keycodes!$E:$E,MATCH(F5,keycodes!$A:$A,0),0)<>"",INDEX(keycodes!$E:$E,MATCH(F5,keycodes!$A:$A,0),0),INDEX(keycodes!$C:$C,MATCH(F5,keycodes!$A:$A,0),0)),INDEX(keycodes!$C:$C,MATCH(F5,keycodes!$B:$B,0),0))) -> KC_V | G31: =IF(G5="",keycodes!$C$2,IF($B$1="Japanese",IF(INDEX(keycodes!$E:$E,MATCH(G5,keycodes!$A:$A,0),0)<>"",INDEX(keycodes!$E:$E,MATCH(G5,keycodes!$A:$A,0),0),INDEX(keycodes!$C:$C,MATCH(G5,keycodes!$A:$A,0),0)),INDEX(keycodes!$C:$C,MATCH(G5,keycodes!$B:$B,0),0))) -> KC_B | H31: =IF(H5="",keycodes!$C$2,IF($B$1="Japanese",IF(INDEX(keycodes!$E:$E,MATCH(H5,keycodes!$A:$A,0),0)<>"",INDEX(keycodes!$E:$E,MATCH(H5,keycodes!$A:$A,0),0),INDEX(keycodes!$C:$C,MATCH(H5,keycodes!$A:$A,0),0)),INDEX(keycodes!$C:$C,MATCH(H5,keycodes!$B:$B,0),0))) -> NONE | I31: =IF(I5="",keycodes!$C$2,IF($B$1="Japanese",IF(INDEX(keycodes!$E:$E,MATCH(I5,keycodes!$A:$A,0),0)<>"",INDEX(keycodes!$E:$E,MATCH(I5,keycodes!$A:$A,0),0),INDEX(keycodes!$C:$C,MATCH(I5,keycodes!$A:$A,0),0)),INDEX(keycodes!$C:$C,MATCH(I5,keycodes!$B:$B,0),0))) -> NONE | ... O31: =IF(O5="",keycodes!$C$2,IF($B$1="Japanese",IF(INDEX(keycodes!$E:$E,MATCH(O5,keycodes!$A:$A,0),0)<>"",INDEX(keycodes!$E:$E,MATCH(O5,keycodes!$A:$A,0),0),INDEX(keycodes!$C:$C,MATCH(O5,keycodes!$A:$A,0),0)),INDEX(keycodes!$C:$C,MATCH(O5,keycodes!$B:$B,0),0))) -> KC_INT1
B32: =IF(B6="",keycodes!$C$2,IF($B$1="Japanese",IF(INDEX(keycodes!$E:$E,MATCH(B6,keycodes!$A:$A,0),0)<>"",INDEX(keycodes!$E:$E,MATCH(B6,keycodes!$A:$A,0),0),INDEX(keycodes!$C:$C,MATCH(B6,keycodes!$A:$A,0),0)),INDEX(keycodes!$C:$C,MATCH(B6,keycodes!$B:$B,0),0))) -> NONE | C32: =IF(C6="",keycodes!$C$2,IF($B$1="Japanese",IF(INDEX(keycodes!$E:$E,MATCH(C6,keycodes!$A:$A,0),0)<>"",INDEX(keycodes!$E:$E,MATCH(C6,keycodes!$A:$A,0),0),INDEX(keycodes!$C:$C,MATCH(C6,keycodes!$A:$A,0),0)),INDEX(keycodes!$C:$C,MATCH(C6,keycodes!$B:$B,0),0))) -> NONE | D32: =IF(D6="",keycodes!$C$2,IF($B$1="Japanese",IF(INDEX(keycodes!$E:$E,MATCH(D6,keycodes!$A:$A,0),0)<>"",INDEX(keycodes!$E:$E,MATCH(D6,keycodes!$A:$A,0),0),INDEX(keycodes!$C:$C,MATCH(D6,keycodes!$A:$A,0),0)),INDEX(keycodes!$C:$C,MATCH(D6,keycodes!$B:$B,0),0))) -> NONE | E32: =IF(E6="",keycodes!$C$2,IF($B$1="Japanese",IF(INDEX(keycodes!$E:$E,MATCH(E6,keycodes!$A:$A,0),0)<>"",INDEX(keycodes!$E:$E,MATCH(E6,keycodes!$A:$A,0),0),INDEX(keycodes!$C:$C,MATCH(E6,keycodes!$A:$A,0),0)),INDEX(keycodes!$C:$C,MATCH(E6,keycodes!$B:$B,0),0))) -> NONE | F32: =IF(F6="",keycodes!$C$2,IF($B$1="Japanese",IF(INDEX(keycodes!$E:$E,MATCH(F6,keycodes!$A:$A,0),0)<>"",INDEX(keycodes!$E:$E,MATCH(F6,keycodes!$A:$A,0),0),INDEX(keycodes!$C:$C,MATCH(F6,keycodes!$A:$A,0),0)),INDEX(keycodes!$C:$C,MATCH(F6,keycodes!$B:$B,0),0))) -> TG_R | G32: =IF(G6="",keycodes!$C$2,IF($B$1="Japanese",IF(INDEX(keycodes!$E:$E,MATCH(G6,keycodes!$A:$A,0),0)<>"",INDEX(keycodes!$E:$E,MATCH(G6,keycodes!$A:$A,0),0),INDEX(keycodes!$C:$C,MATCH(G6,keycodes!$A:$A,0),0)),INDEX(keycodes!$C:$C,MATCH(G6,keycodes!$B:$B,0),0))) -> MO_R | H32: =IF(H6="",keycodes!$C$2,IF($B$1="Japanese",IF(INDEX(keycodes!$E:$E,MATCH(H6,keycodes!$A:$A,0),0)<>"",INDEX(keycodes!$E:$E,MATCH(H6,keycodes!$A:$A,0),0),INDEX(keycodes!$C:$C,MATCH(H6,keycodes!$A:$A,0),0)),INDEX(keycodes!$C:$C,MATCH(H6,keycodes!$B:$B,0),0))) -> LSFT_SPC | I32: =IF(I6="",keycodes!$C$2,IF($B$1="Japanese",IF(INDEX(keycodes!$E:$E,MATCH(I6,keycodes!$A:$A,0),0)<>"",INDEX(keycodes!$E:$E,MATCH(I6,keycodes!$A:$A,0),0),INDEX(keycodes!$C:$C,MATCH(I6,keycodes!$A:$A,0),0)),INDEX(keycodes!$C:$C,MATCH(I6,keycodes!$B:$B,0),0))) -> RSTF_ENT | ... O32: =IF(O6="",keycodes!$C$2,IF($B$1="Japanese",IF(INDEX(keycodes!$E:$E,MATCH(O6,keycodes!$A:$A,0),0)<>"",INDEX(keycodes!$E:$E,MATCH(O6,keycodes!$A:$A,0),0),INDEX(keycodes!$C:$C,MATCH(O6,keycodes!$A:$A,0),0)),INDEX(keycodes!$C:$C,MATCH(O6,keycodes!$B:$B,0),0))) -> TERM
A33: LOWER | B33: =IF(B7="",keycodes!$C$2,IF($B$1="Japanese",IF(INDEX(keycodes!$E:$E,MATCH(B7,keycodes!$A:$A,0),0)<>"",INDEX(keycodes!$E:$E,MATCH(B7,keycodes!$A:$A,0),0),INDEX(keycodes!$C:$C,MATCH(B7,keycodes!$A:$A,0),0)),INDEX(keycodes!$C:$C,MATCH(B7,keycodes!$B:$B,0),0))) -> KC_APP | C33: =IF(C7="",keycodes!$C$2,IF($B$1="Japanese",IF(INDEX(keycodes!$E:$E,MATCH(C7,keycodes!$A:$A,0),0)<>"",INDEX(keycodes!$E:$E,MATCH(C7,keycodes!$A:$A,0),0),INDEX(keycodes!$C:$C,MATCH(C7,keycodes!$A:$A,0),0)),INDEX(keycodes!$C:$C,MATCH(C7,keycodes!$B:$B,0),0))) -> S(KC_1) | D33: =IF(D7="",keycodes!$C$2,IF($B$1="Japanese",IF(INDEX(keycodes!$E:$E,MATCH(D7,keycodes!$A:$A,0),0)<>"",INDEX(keycodes!$E:$E,MATCH(D7,keycodes!$A:$A,0),0),INDEX(keycodes!$C:$C,MATCH(D7,keycodes!$A:$A,0),0)),INDEX(keycodes!$C:$C,MATCH(D7,keycodes!$B:$B,0),0))) -> S(KC_2) | E33: =IF(E7="",keycodes!$C$2,IF($B$1="Japanese",IF(INDEX(keycodes!$E:$E,MATCH(E7,keycodes!$A:$A,0),0)<>"",INDEX(keycodes!$E:$E,MATCH(E7,keycodes!$A:$A,0),0),INDEX(keycodes!$C:$C,MATCH(E7,keycodes!$A:$A,0),0)),INDEX(keycodes!$C:$C,MATCH(E7,keycodes!$B:$B,0),0))) -> S(KC_3) | F33: =IF(F7="",keycodes!$C$2,IF($B$1="Japanese",IF(INDEX(keycodes!$E:$E,MATCH(F7,keycodes!$A:$A,0),0)<>"",INDEX(keycodes!$E:$E,MATCH(F7,keycodes!$A:$A,0),0),INDEX(keycodes!$C:$C,MATCH(F7,keycodes!$A:$A,0),0)),INDEX(keycodes!$C:$C,MATCH(F7,keycodes!$B:$B,0),0))) -> S(KC_4) | G33: =IF(G7="",keycodes!$C$2,IF($B$1="Japanese",IF(INDEX(keycodes!$E:$E,MATCH(G7,keycodes!$A:$A,0),0)<>"",INDEX(keycodes!$E:$E,MATCH(G7,keycodes!$A:$A,0),0),INDEX(keycodes!$C:$C,MATCH(G7,keycodes!$A:$A,0),0)),INDEX(keycodes!$C:$C,MATCH(G7,keycodes!$B:$B,0),0))) -> S(KC_5) | H33: =IF(H7="",keycodes!$C$2,IF($B$1="Japanese",IF(INDEX(keycodes!$E:$E,MATCH(H7,keycodes!$A:$A,0),0)<>"",INDEX(keycodes!$E:$E,MATCH(H7,keycodes!$A:$A,0),0),INDEX(keycodes!$C:$C,MATCH(H7,keycodes!$A:$A,0),0)),INDEX(keycodes!$C:$C,MATCH(H7,keycodes!$B:$B,0),0))) -> NONE | I33: =IF(I7="",keycodes!$C$2,IF($B$1="Japanese",IF(INDEX(keycodes!$E:$E,MATCH(I7,keycodes!$A:$A,0),0)<>"",INDEX(keycodes!$E:$E,MATCH(I7,keycodes!$A:$A,0),0),INDEX(keycodes!$C:$C,MATCH(I7,keycodes!$A:$A,0),0)),INDEX(keycodes!$C:$C,MATCH(I7,keycodes!$B:$B,0),0))) -> NONE | ... O33: =IF(O7="",keycodes!$C$2,IF($B$1="Japanese",IF(INDEX(keycodes!$E:$E,MATCH(O7,keycodes!$A:$A,0),0)<>"",INDEX(keycodes!$E:$E,MATCH(O7,keycodes!$A:$A,0),0),INDEX(keycodes!$C:$C,MATCH(O7,keycodes!$A:$A,0),0)),INDEX(keycodes!$C:$C,MATCH(O7,keycodes!$B:$B,0),0))) -> S(KC_LBRC)
B34: =IF(B8="",keycodes!$C$2,IF($B$1="Japanese",IF(INDEX(keycodes!$E:$E,MATCH(B8,keycodes!$A:$A,0),0)<>"",INDEX(keycodes!$E:$E,MATCH(B8,keycodes!$A:$A,0),0),INDEX(keycodes!$C:$C,MATCH(B8,keycodes!$A:$A,0),0)),INDEX(keycodes!$C:$C,MATCH(B8,keycodes!$B:$B,0),0))) -> KC_LGUI | C34: =IF(C8="",keycodes!$C$2,IF($B$1="Japanese",IF(INDEX(keycodes!$E:$E,MATCH(C8,keycodes!$A:$A,0),0)<>"",INDEX(keycodes!$E:$E,MATCH(C8,keycodes!$A:$A,0),0),INDEX(keycodes!$C:$C,MATCH(C8,keycodes!$A:$A,0),0)),INDEX(keycodes!$C:$C,MATCH(C8,keycodes!$B:$B,0),0))) -> XXXXXXX | D34: =IF(D8="",keycodes!$C$2,IF($B$1="Japanese",IF(INDEX(keycodes!$E:$E,MATCH(D8,keycodes!$A:$A,0),0)<>"",INDEX(keycodes!$E:$E,MATCH(D8,keycodes!$A:$A,0),0),INDEX(keycodes!$C:$C,MATCH(D8,keycodes!$A:$A,0),0)),INDEX(keycodes!$C:$C,MATCH(D8,keycodes!$B:$B,0),0))) -> KC_HOME | E34: =IF(E8="",keycodes!$C$2,IF($B$1="Japanese",IF(INDEX(keycodes!$E:$E,MATCH(E8,keycodes!$A:$A,0),0)<>"",INDEX(keycodes!$E:$E,MATCH(E8,keycodes!$A:$A,0),0),INDEX(keycodes!$C:$C,MATCH(E8,keycodes!$A:$A,0),0)),INDEX(keycodes!$C:$C,MATCH(E8,keycodes!$B:$B,0),0))) -> KC_PGUP | F34: =IF(F8="",keycodes!$C$2,IF($B$1="Japanese",IF(INDEX(keycodes!$E:$E,MATCH(F8,keycodes!$A:$A,0),0)<>"",INDEX(keycodes!$E:$E,MATCH(F8,keycodes!$A:$A,0),0),INDEX(keycodes!$C:$C,MATCH(F8,keycodes!$A:$A,0),0)),INDEX(keycodes!$C:$C,MATCH(F8,keycodes!$B:$B,0),0))) -> KC_PGDN | G34: =IF(G8="",keycodes!$C$2,IF($B$1="Japanese",IF(INDEX(keycodes!$E:$E,MATCH(G8,keycodes!$A:$A,0),0)<>"",INDEX(keycodes!$E:$E,MATCH(G8,keycodes!$A:$A,0),0),INDEX(keycodes!$C:$C,MATCH(G8,keycodes!$A:$A,0),0)),INDEX(keycodes!$C:$C,MATCH(G8,keycodes!$B:$B,0),0))) -> KC_END | H34: =IF(H8="",keycodes!$C$2,IF($B$1="Japanese",IF(INDEX(keycodes!$E:$E,MATCH(H8,keycodes!$A:$A,0),0)<>"",INDEX(keycodes!$E:$E,MATCH(H8,keycodes!$A:$A,0),0),INDEX(keycodes!$C:$C,MATCH(H8,keycodes!$A:$A,0),0)),INDEX(keycodes!$C:$C,MATCH(H8,keycodes!$B:$B,0),0))) -> NONE | I34: =IF(I8="",keycodes!$C$2,IF($B$1="Japanese",IF(INDEX(keycodes!$E:$E,MATCH(I8,keycodes!$A:$A,0),0)<>"",INDEX(keycodes!$E:$E,MATCH(I8,keycodes!$A:$A,0),0),INDEX(keycodes!$C:$C,MATCH(I8,keycodes!$A:$A,0),0)),INDEX(keycodes!$C:$C,MATCH(I8,keycodes!$B:$B,0),0))) -> NONE | ... O34: =IF(O8="",keycodes!$C$2,IF($B$1="Japanese",IF(INDEX(keycodes!$E:$E,MATCH(O8,keycodes!$A:$A,0),0)<>"",INDEX(keycodes!$E:$E,MATCH(O8,keycodes!$A:$A,0),0),INDEX(keycodes!$C:$C,MATCH(O8,keycodes!$A:$A,0),0)),INDEX(keycodes!$C:$C,MATCH(O8,keycodes!$B:$B,0),0))) -> KC_MINS
B35: =IF(B9="",keycodes!$C$2,IF($B$1="Japanese",IF(INDEX(keycodes!$E:$E,MATCH(B9,keycodes!$A:$A,0),0)<>"",INDEX(keycodes!$E:$E,MATCH(B9,keycodes!$A:$A,0),0),INDEX(keycodes!$C:$C,MATCH(B9,keycodes!$A:$A,0),0)),INDEX(keycodes!$C:$C,MATCH(B9,keycodes!$B:$B,0),0))) -> _______ | C35: =IF(C9="",keycodes!$C$2,IF($B$1="Japanese",IF(INDEX(keycodes!$E:$E,MATCH(C9,keycodes!$A:$A,0),0)<>"",INDEX(keycodes!$E:$E,MATCH(C9,keycodes!$A:$A,0),0),INDEX(keycodes!$C:$C,MATCH(C9,keycodes!$A:$A,0),0)),INDEX(keycodes!$C:$C,MATCH(C9,keycodes!$B:$B,0),0))) -> KC_LALT | D35: =IF(D9="",keycodes!$C$2,IF($B$1="Japanese",IF(INDEX(keycodes!$E:$E,MATCH(D9,keycodes!$A:$A,0),0)<>"",INDEX(keycodes!$E:$E,MATCH(D9,keycodes!$A:$A,0),0),INDEX(keycodes!$C:$C,MATCH(D9,keycodes!$A:$A,0),0)),INDEX(keycodes!$C:$C,MATCH(D9,keycodes!$B:$B,0),0))) -> XXXXXXX | E35: =IF(E9="",keycodes!$C$2,IF($B$1="Japanese",IF(INDEX(keycodes!$E:$E,MATCH(E9,keycodes!$A:$A,0),0)<>"",INDEX(keycodes!$E:$E,MATCH(E9,keycodes!$A:$A,0),0),INDEX(keycodes!$C:$C,MATCH(E9,keycodes!$A:$A,0),0)),INDEX(keycodes!$C:$C,MATCH(E9,keycodes!$B:$B,0),0))) -> XXXXXXX | F35: =IF(F9="",keycodes!$C$2,IF($B$1="Japanese",IF(INDEX(keycodes!$E:$E,MATCH(F9,keycodes!$A:$A,0),0)<>"",INDEX(keycodes!$E:$E,MATCH(F9,keycodes!$A:$A,0),0),INDEX(keycodes!$C:$C,MATCH(F9,keycodes!$A:$A,0),0)),INDEX(keycodes!$C:$C,MATCH(F9,keycodes!$B:$B,0),0))) -> KC_INT5 | G35: =IF(G9="",keycodes!$C$2,IF($B$1="Japanese",IF(INDEX(keycodes!$E:$E,MATCH(G9,keycodes!$A:$A,0),0)<>"",INDEX(keycodes!$E:$E,MATCH(G9,keycodes!$A:$A,0),0),INDEX(keycodes!$C:$C,MATCH(G9,keycodes!$A:$A,0),0)),INDEX(keycodes!$C:$C,MATCH(G9,keycodes!$B:$B,0),0))) -> KC_BSPC | H35: =IF(H9="",keycodes!$C$2,IF($B$1="Japanese",IF(INDEX(keycodes!$E:$E,MATCH(H9,keycodes!$A:$A,0),0)<>"",INDEX(keycodes!$E:$E,MATCH(H9,keycodes!$A:$A,0),0),INDEX(keycodes!$C:$C,MATCH(H9,keycodes!$A:$A,0),0)),INDEX(keycodes!$C:$C,MATCH(H9,keycodes!$B:$B,0),0))) -> NONE | I35: =IF(I9="",keycodes!$C$2,IF($B$1="Japanese",IF(INDEX(keycodes!$E:$E,MATCH(I9,keycodes!$A:$A,0),0)<>"",INDEX(keycodes!$E:$E,MATCH(I9,keycodes!$A:$A,0),0),INDEX(keycodes!$C:$C,MATCH(I9,keycodes!$A:$A,0),0)),INDEX(keycodes!$C:$C,MATCH(I9,keycodes!$B:$B,0),0))) -> NONE | ... O35: =IF(O9="",keycodes!$C$2,IF($B$1="Japanese",IF(INDEX(keycodes!$E:$E,MATCH(O9,keycodes!$A:$A,0),0)<>"",INDEX(keycodes!$E:$E,MATCH(O9,keycodes!$A:$A,0),0),INDEX(keycodes!$C:$C,MATCH(O9,keycodes!$A:$A,0),0)),INDEX(keycodes!$C:$C,MATCH(O9,keycodes!$B:$B,0),0))) -> S(KC_INT3)
B36: =IF(B10="",keycodes!$C$2,IF($B$1="Japanese",IF(INDEX(keycodes!$E:$E,MATCH(B10,keycodes!$A:$A,0),0)<>"",INDEX(keycodes!$E:$E,MATCH(B10,keycodes!$A:$A,0),0),INDEX(keycodes!$C:$C,MATCH(B10,keycodes!$A:$A,0),0)),INDEX(keycodes!$C:$C,MATCH(B10,keycodes!$B:$B,0),0))) -> NONE | C36: =IF(C10="",keycodes!$C$2,IF($B$1="Japanese",IF(INDEX(keycodes!$E:$E,MATCH(C10,keycodes!$A:$A,0),0)<>"",INDEX(keycodes!$E:$E,MATCH(C10,keycodes!$A:$A,0),0),INDEX(keycodes!$C:$C,MATCH(C10,keycodes!$A:$A,0),0)),INDEX(keycodes!$C:$C,MATCH(C10,keycodes!$B:$B,0),0))) -> NONE | D36: =IF(D10="",keycodes!$C$2,IF($B$1="Japanese",IF(INDEX(keycodes!$E:$E,MATCH(D10,keycodes!$A:$A,0),0)<>"",INDEX(keycodes!$E:$E,MATCH(D10,keycodes!$A:$A,0),0),INDEX(keycodes!$C:$C,MATCH(D10,keycodes!$A:$A,0),0)),INDEX(keycodes!$C:$C,MATCH(D10,keycodes!$B:$B,0),0))) -> NONE | E36: =IF(E10="",keycodes!$C$2,IF($B$1="Japanese",IF(INDEX(keycodes!$E:$E,MATCH(E10,keycodes!$A:$A,0),0)<>"",INDEX(keycodes!$E:$E,MATCH(E10,keycodes!$A:$A,0),0),INDEX(keycodes!$C:$C,MATCH(E10,keycodes!$A:$A,0),0)),INDEX(keycodes!$C:$C,MATCH(E10,keycodes!$B:$B,0),0))) -> NONE | F36: =IF(F10="",keycodes!$C$2,IF($B$1="Japanese",IF(INDEX(keycodes!$E:$E,MATCH(F10,keycodes!$A:$A,0),0)<>"",INDEX(keycodes!$E:$E,MATCH(F10,keycodes!$A:$A,0),0),INDEX(keycodes!$C:$C,MATCH(F10,keycodes!$A:$A,0),0)),INDEX(keycodes!$C:$C,MATCH(F10,keycodes!$B:$B,0),0))) -> _______ | G36: =IF(G10="",keycodes!$C$2,IF($B$1="Japanese",IF(INDEX(keycodes!$E:$E,MATCH(G10,keycodes!$A:$A,0),0)<>"",INDEX(keycodes!$E:$E,MATCH(G10,keycodes!$A:$A,0),0),INDEX(keycodes!$C:$C,MATCH(G10,keycodes!$A:$A,0),0)),INDEX(keycodes!$C:$C,MATCH(G10,keycodes!$B:$B,0),0))) -> _______ | H36: =IF(H10="",keycodes!$C$2,IF($B$1="Japanese",IF(INDEX(keycodes!$E:$E,MATCH(H10,keycodes!$A:$A,0),0)<>"",INDEX(keycodes!$E:$E,MATCH(H10,keycodes!$A:$A,0),0),INDEX(keycodes!$C:$C,MATCH(H10,keycodes!$A:$A,0),0)),INDEX(keycodes!$C:$C,MATCH(H10,keycodes!$B:$B,0),0))) -> _______ | I36: =IF(I10="",keycodes!$C$2,IF($B$1="Japanese",IF(INDEX(keycodes!$E:$E,MATCH(I10,keycodes!$A:$A,0),0)<>"",INDEX(keycodes!$E:$E,MATCH(I10,keycodes!$A:$A,0),0),INDEX(keycodes!$C:$C,MATCH(I10,keycodes!$A:$A,0),0)),INDEX(keycodes!$C:$C,MATCH(I10,keycodes!$B:$B,0),0))) -> _______ | ... O36: =IF(O10="",keycodes!$C$2,IF($B$1="Japanese",IF(INDEX(keycodes!$E:$E,MATCH(O10,keycodes!$A:$A,0),0)<>"",INDEX(keycodes!$E:$E,MATCH(O10,keycodes!$A:$A,0),0),INDEX(keycodes!$C:$C,MATCH(O10,keycodes!$A:$A,0),0)),INDEX(keycodes!$C:$C,MATCH(O10,keycodes!$B:$B,0),0))) -> TERM
A37: RAISE | B37: =IF(B11="",keycodes!$C$2,IF($B$1="Japanese",IF(INDEX(keycodes!$E:$E,MATCH(B11,keycodes!$A:$A,0),0)<>"",INDEX(keycodes!$E:$E,MATCH(B11,keycodes!$A:$A,0),0),INDEX(keycodes!$C:$C,MATCH(B11,keycodes!$A:$A,0),0)),INDEX(keycodes!$C:$C,MATCH(B11,keycodes!$B:$B,0),0))) -> KC_F1 | C37: =IF(C11="",keycodes!$C$2,IF($B$1="Japanese",IF(INDEX(keycodes!$E:$E,MATCH(C11,keycodes!$A:$A,0),0)<>"",INDEX(keycodes!$E:$E,MATCH(C11,keycodes!$A:$A,0),0),INDEX(keycodes!$C:$C,MATCH(C11,keycodes!$A:$A,0),0)),INDEX(keycodes!$C:$C,MATCH(C11,keycodes!$B:$B,0),0))) -> KC_F2 | D37: =IF(D11="",keycodes!$C$2,IF($B$1="Japanese",IF(INDEX(keycodes!$E:$E,MATCH(D11,keycodes!$A:$A,0),0)<>"",INDEX(keycodes!$E:$E,MATCH(D11,keycodes!$A:$A,0),0),INDEX(keycodes!$C:$C,MATCH(D11,keycodes!$A:$A,0),0)),INDEX(keycodes!$C:$C,MATCH(D11,keycodes!$B:$B,0),0))) -> KC_F3 | E37: =IF(E11="",keycodes!$C$2,IF($B$1="Japanese",IF(INDEX(keycodes!$E:$E,MATCH(E11,keycodes!$A:$A,0),0)<>"",INDEX(keycodes!$E:$E,MATCH(E11,keycodes!$A:$A,0),0),INDEX(keycodes!$C:$C,MATCH(E11,keycodes!$A:$A,0),0)),INDEX(keycodes!$C:$C,MATCH(E11,keycodes!$B:$B,0),0))) -> KC_F4 | F37: =IF(F11="",keycodes!$C$2,IF($B$1="Japanese",IF(INDEX(keycodes!$E:$E,MATCH(F11,keycodes!$A:$A,0),0)<>"",INDEX(keycodes!$E:$E,MATCH(F11,keycodes!$A:$A,0),0),INDEX(keycodes!$C:$C,MATCH(F11,keycodes!$A:$A,0),0)),INDEX(keycodes!$C:$C,MATCH(F11,keycodes!$B:$B,0),0))) -> KC_F5 | G37: =IF(G11="",keycodes!$C$2,IF($B$1="Japanese",IF(INDEX(keycodes!$E:$E,MATCH(G11,keycodes!$A:$A,0),0)<>"",INDEX(keycodes!$E:$E,MATCH(G11,keycodes!$A:$A,0),0),INDEX(keycodes!$C:$C,MATCH(G11,keycodes!$A:$A,0),0)),INDEX(keycodes!$C:$C,MATCH(G11,keycodes!$B:$B,0),0))) -> KC_F6 | H37: =IF(H11="",keycodes!$C$2,IF($B$1="Japanese",IF(INDEX(keycodes!$E:$E,MATCH(H11,keycodes!$A:$A,0),0)<>"",INDEX(keycodes!$E:$E,MATCH(H11,keycodes!$A:$A,0),0),INDEX(keycodes!$C:$C,MATCH(H11,keycodes!$A:$A,0),0)),INDEX(keycodes!$C:$C,MATCH(H11,keycodes!$B:$B,0),0))) -> NONE | I37: =IF(I11="",keycodes!$C$2,IF($B$1="Japanese",IF(INDEX(keycodes!$E:$E,MATCH(I11,keycodes!$A:$A,0),0)<>"",INDEX(keycodes!$E:$E,MATCH(I11,keycodes!$A:$A,0),0),INDEX(keycodes!$C:$C,MATCH(I11,keycodes!$A:$A,0),0)),INDEX(keycodes!$C:$C,MATCH(I11,keycodes!$B:$B,0),0))) -> NONE | ... O37: =IF(O11="",keycodes!$C$2,IF($B$1="Japanese",IF(INDEX(keycodes!$E:$E,MATCH(O11,keycodes!$A:$A,0),0)<>"",INDEX(keycodes!$E:$E,MATCH(O11,keycodes!$A:$A,0),0),INDEX(keycodes!$C:$C,MATCH(O11,keycodes!$A:$A,0),0)),INDEX(keycodes!$C:$C,MATCH(O11,keycodes!$B:$B,0),0))) -> KC_F12
B38: =IF(B12="",keycodes!$C$2,IF($B$1="Japanese",IF(INDEX(keycodes!$E:$E,MATCH(B12,keycodes!$A:$A,0),0)<>"",INDEX(keycodes!$E:$E,MATCH(B12,keycodes!$A:$A,0),0),INDEX(keycodes!$C:$C,MATCH(B12,keycodes!$A:$A,0),0)),INDEX(keycodes!$C:$C,MATCH(B12,keycodes!$B:$B,0),0))) -> KC_GRV | C38: =IF(C12="",keycodes!$C$2,IF($B$1="Japanese",IF(INDEX(keycodes!$E:$E,MATCH(C12,keycodes!$A:$A,0),0)<>"",INDEX(keycodes!$E:$E,MATCH(C12,keycodes!$A:$A,0),0),INDEX(keycodes!$C:$C,MATCH(C12,keycodes!$A:$A,0),0)),INDEX(keycodes!$C:$C,MATCH(C12,keycodes!$B:$B,0),0))) -> KC_1 | D38: =IF(D12="",keycodes!$C$2,IF($B$1="Japanese",IF(INDEX(keycodes!$E:$E,MATCH(D12,keycodes!$A:$A,0),0)<>"",INDEX(keycodes!$E:$E,MATCH(D12,keycodes!$A:$A,0),0),INDEX(keycodes!$C:$C,MATCH(D12,keycodes!$A:$A,0),0)),INDEX(keycodes!$C:$C,MATCH(D12,keycodes!$B:$B,0),0))) -> KC_2 | E38: =IF(E12="",keycodes!$C$2,IF($B$1="Japanese",IF(INDEX(keycodes!$E:$E,MATCH(E12,keycodes!$A:$A,0),0)<>"",INDEX(keycodes!$E:$E,MATCH(E12,keycodes!$A:$A,0),0),INDEX(keycodes!$C:$C,MATCH(E12,keycodes!$A:$A,0),0)),INDEX(keycodes!$C:$C,MATCH(E12,keycodes!$B:$B,0),0))) -> KC_3 | F38: =IF(F12="",keycodes!$C$2,IF($B$1="Japanese",IF(INDEX(keycodes!$E:$E,MATCH(F12,keycodes!$A:$A,0),0)<>"",INDEX(keycodes!$E:$E,MATCH(F12,keycodes!$A:$A,0),0),INDEX(keycodes!$C:$C,MATCH(F12,keycodes!$A:$A,0),0)),INDEX(keycodes!$C:$C,MATCH(F12,keycodes!$B:$B,0),0))) -> KC_4 | G38: =IF(G12="",keycodes!$C$2,IF($B$1="Japanese",IF(INDEX(keycodes!$E:$E,MATCH(G12,keycodes!$A:$A,0),0)<>"",INDEX(keycodes!$E:$E,MATCH(G12,keycodes!$A:$A,0),0),INDEX(keycodes!$C:$C,MATCH(G12,keycodes!$A:$A,0),0)),INDEX(keycodes!$C:$C,MATCH(G12,keycodes!$B:$B,0),0))) -> KC_5 | H38: =IF(H12="",keycodes!$C$2,IF($B$1="Japanese",IF(INDEX(keycodes!$E:$E,MATCH(H12,keycodes!$A:$A,0),0)<>"",INDEX(keycodes!$E:$E,MATCH(H12,keycodes!$A:$A,0),0),INDEX(keycodes!$C:$C,MATCH(H12,keycodes!$A:$A,0),0)),INDEX(keycodes!$C:$C,MATCH(H12,keycodes!$B:$B,0),0))) -> NONE | I38: =IF(I12="",keycodes!$C$2,IF($B$1="Japanese",IF(INDEX(keycodes!$E:$E,MATCH(I12,keycodes!$A:$A,0),0)<>"",INDEX(keycodes!$E:$E,MATCH(I12,keycodes!$A:$A,0),0),INDEX(keycodes!$C:$C,MATCH(I12,keycodes!$A:$A,0),0)),INDEX(keycodes!$C:$C,MATCH(I12,keycodes!$B:$B,0),0))) -> NONE | ... O38: =IF(O12="",keycodes!$C$2,IF($B$1="Japanese",IF(INDEX(keycodes!$E:$E,MATCH(O12,keycodes!$A:$A,0),0)<>"",INDEX(keycodes!$E:$E,MATCH(O12,keycodes!$A:$A,0),0),INDEX(keycodes!$C:$C,MATCH(O12,keycodes!$A:$A,0),0)),INDEX(keycodes!$C:$C,MATCH(O12,keycodes!$B:$B,0),0))) -> _______
B39: =IF(B13="",keycodes!$C$2,IF($B$1="Japanese",IF(INDEX(keycodes!$E:$E,MATCH(B13,keycodes!$A:$A,0),0)<>"",INDEX(keycodes!$E:$E,MATCH(B13,keycodes!$A:$A,0),0),INDEX(keycodes!$C:$C,MATCH(B13,keycodes!$A:$A,0),0)),INDEX(keycodes!$C:$C,MATCH(B13,keycodes!$B:$B,0),0))) -> _______ | C39: =IF(C13="",keycodes!$C$2,IF($B$1="Japanese",IF(INDEX(keycodes!$E:$E,MATCH(C13,keycodes!$A:$A,0),0)<>"",INDEX(keycodes!$E:$E,MATCH(C13,keycodes!$A:$A,0),0),INDEX(keycodes!$C:$C,MATCH(C13,keycodes!$A:$A,0),0)),INDEX(keycodes!$C:$C,MATCH(C13,keycodes!$B:$B,0),0))) -> _______ | D39: =IF(D13="",keycodes!$C$2,IF($B$1="Japanese",IF(INDEX(keycodes!$E:$E,MATCH(D13,keycodes!$A:$A,0),0)<>"",INDEX(keycodes!$E:$E,MATCH(D13,keycodes!$A:$A,0),0),INDEX(keycodes!$C:$C,MATCH(D13,keycodes!$A:$A,0),0)),INDEX(keycodes!$C:$C,MATCH(D13,keycodes!$B:$B,0),0))) -> MS_WHLL | E39: =IF(E13="",keycodes!$C$2,IF($B$1="Japanese",IF(INDEX(keycodes!$E:$E,MATCH(E13,keycodes!$A:$A,0),0)<>"",INDEX(keycodes!$E:$E,MATCH(E13,keycodes!$A:$A,0),0),INDEX(keycodes!$C:$C,MATCH(E13,keycodes!$A:$A,0),0)),INDEX(keycodes!$C:$C,MATCH(E13,keycodes!$B:$B,0),0))) -> MS_WHLR | F39: =IF(F13="",keycodes!$C$2,IF($B$1="Japanese",IF(INDEX(keycodes!$E:$E,MATCH(F13,keycodes!$A:$A,0),0)<>"",INDEX(keycodes!$E:$E,MATCH(F13,keycodes!$A:$A,0),0),INDEX(keycodes!$C:$C,MATCH(F13,keycodes!$A:$A,0),0)),INDEX(keycodes!$C:$C,MATCH(F13,keycodes!$B:$B,0),0))) -> _______ | G39: =IF(G13="",keycodes!$C$2,IF($B$1="Japanese",IF(INDEX(keycodes!$E:$E,MATCH(G13,keycodes!$A:$A,0),0)<>"",INDEX(keycodes!$E:$E,MATCH(G13,keycodes!$A:$A,0),0),INDEX(keycodes!$C:$C,MATCH(G13,keycodes!$A:$A,0),0)),INDEX(keycodes!$C:$C,MATCH(G13,keycodes!$B:$B,0),0))) -> _______ | H39: =IF(H13="",keycodes!$C$2,IF($B$1="Japanese",IF(INDEX(keycodes!$E:$E,MATCH(H13,keycodes!$A:$A,0),0)<>"",INDEX(keycodes!$E:$E,MATCH(H13,keycodes!$A:$A,0),0),INDEX(keycodes!$C:$C,MATCH(H13,keycodes!$A:$A,0),0)),INDEX(keycodes!$C:$C,MATCH(H13,keycodes!$B:$B,0),0))) -> NONE | I39: =IF(I13="",keycodes!$C$2,IF($B$1="Japanese",IF(INDEX(keycodes!$E:$E,MATCH(I13,keycodes!$A:$A,0),0)<>"",INDEX(keycodes!$E:$E,MATCH(I13,keycodes!$A:$A,0),0),INDEX(keycodes!$C:$C,MATCH(I13,keycodes!$A:$A,0),0)),INDEX(keycodes!$C:$C,MATCH(I13,keycodes!$B:$B,0),0))) -> NONE | ... O39: =IF(O13="",keycodes!$C$2,IF($B$1="Japanese",IF(INDEX(keycodes!$E:$E,MATCH(O13,keycodes!$A:$A,0),0)<>"",INDEX(keycodes!$E:$E,MATCH(O13,keycodes!$A:$A,0),0),INDEX(keycodes!$C:$C,MATCH(O13,keycodes!$A:$A,0),0)),INDEX(keycodes!$C:$C,MATCH(O13,keycodes!$B:$B,0),0))) -> KC_INT1
B40: =IF(B14="",keycodes!$C$2,IF($B$1="Japanese",IF(INDEX(keycodes!$E:$E,MATCH(B14,keycodes!$A:$A,0),0)<>"",INDEX(keycodes!$E:$E,MATCH(B14,keycodes!$A:$A,0),0),INDEX(keycodes!$C:$C,MATCH(B14,keycodes!$A:$A,0),0)),INDEX(keycodes!$C:$C,MATCH(B14,keycodes!$B:$B,0),0))) -> NONE | C40: =IF(C14="",keycodes!$C$2,IF($B$1="Japanese",IF(INDEX(keycodes!$E:$E,MATCH(C14,keycodes!$A:$A,0),0)<>"",INDEX(keycodes!$E:$E,MATCH(C14,keycodes!$A:$A,0),0),INDEX(keycodes!$C:$C,MATCH(C14,keycodes!$A:$A,0),0)),INDEX(keycodes!$C:$C,MATCH(C14,keycodes!$B:$B,0),0))) -> NONE | D40: =IF(D14="",keycodes!$C$2,IF($B$1="Japanese",IF(INDEX(keycodes!$E:$E,MATCH(D14,keycodes!$A:$A,0),0)<>"",INDEX(keycodes!$E:$E,MATCH(D14,keycodes!$A:$A,0),0),INDEX(keycodes!$C:$C,MATCH(D14,keycodes!$A:$A,0),0)),INDEX(keycodes!$C:$C,MATCH(D14,keycodes!$B:$B,0),0))) -> NONE | E40: =IF(E14="",keycodes!$C$2,IF($B$1="Japanese",IF(INDEX(keycodes!$E:$E,MATCH(E14,keycodes!$A:$A,0),0)<>"",INDEX(keycodes!$E:$E,MATCH(E14,keycodes!$A:$A,0),0),INDEX(keycodes!$C:$C,MATCH(E14,keycodes!$A:$A,0),0)),INDEX(keycodes!$C:$C,MATCH(E14,keycodes!$B:$B,0),0))) -> NONE | F40: =IF(F14="",keycodes!$C$2,IF($B$1="Japanese",IF(INDEX(keycodes!$E:$E,MATCH(F14,keycodes!$A:$A,0),0)<>"",INDEX(keycodes!$E:$E,MATCH(F14,keycodes!$A:$A,0),0),INDEX(keycodes!$C:$C,MATCH(F14,keycodes!$A:$A,0),0)),INDEX(keycodes!$C:$C,MATCH(F14,keycodes!$B:$B,0),0))) -> _______ | G40: =IF(G14="",keycodes!$C$2,IF($B$1="Japanese",IF(INDEX(keycodes!$E:$E,MATCH(G14,keycodes!$A:$A,0),0)<>"",INDEX(keycodes!$E:$E,MATCH(G14,keycodes!$A:$A,0),0),INDEX(keycodes!$C:$C,MATCH(G14,keycodes!$A:$A,0),0)),INDEX(keycodes!$C:$C,MATCH(G14,keycodes!$B:$B,0),0))) -> _______ | H40: =IF(H14="",keycodes!$C$2,IF($B$1="Japanese",IF(INDEX(keycodes!$E:$E,MATCH(H14,keycodes!$A:$A,0),0)<>"",INDEX(keycodes!$E:$E,MATCH(H14,keycodes!$A:$A,0),0),INDEX(keycodes!$C:$C,MATCH(H14,keycodes!$A:$A,0),0)),INDEX(keycodes!$C:$C,MATCH(H14,keycodes!$B:$B,0),0))) -> _______ | I40: =IF(I14="",keycodes!$C$2,IF($B$1="Japanese",IF(INDEX(keycodes!$E:$E,MATCH(I14,keycodes!$A:$A,0),0)<>"",INDEX(keycodes!$E:$E,MATCH(I14,keycodes!$A:$A,0),0),INDEX(keycodes!$C:$C,MATCH(I14,keycodes!$A:$A,0),0)),INDEX(keycodes!$C:$C,MATCH(I14,keycodes!$B:$B,0),0))) -> _______ | ... O40: =IF(O14="",keycodes!$C$2,IF($B$1="Japanese",IF(INDEX(keycodes!$E:$E,MATCH(O14,keycodes!$A:$A,0),0)<>"",INDEX(keycodes!$E:$E,MATCH(O14,keycodes!$A:$A,0),0),INDEX(keycodes!$C:$C,MATCH(O14,keycodes!$A:$A,0),0)),INDEX(keycodes!$C:$C,MATCH(O14,keycodes!$B:$B,0),0))) -> TERM
A41: ADJUST | B41: =IF(B15="",keycodes!$C$2,IF($B$1="Japanese",IF(INDEX(keycodes!$E:$E,MATCH(B15,keycodes!$A:$A,0),0)<>"",INDEX(keycodes!$E:$E,MATCH(B15,keycodes!$A:$A,0),0),INDEX(keycodes!$C:$C,MATCH(B15,keycodes!$A:$A,0),0)),INDEX(keycodes!$C:$C,MATCH(B15,keycodes!$B:$B,0),0))) -> KC_ESC | C41: =IF(C15="",keycodes!$C$2,IF($B$1="Japanese",IF(INDEX(keycodes!$E:$E,MATCH(C15,keycodes!$A:$A,0),0)<>"",INDEX(keycodes!$E:$E,MATCH(C15,keycodes!$A:$A,0),0),INDEX(keycodes!$C:$C,MATCH(C15,keycodes!$A:$A,0),0)),INDEX(keycodes!$C:$C,MATCH(C15,keycodes!$B:$B,0),0))) -> KC_Q | D41: =IF(D15="",keycodes!$C$2,IF($B$1="Japanese",IF(INDEX(keycodes!$E:$E,MATCH(D15,keycodes!$A:$A,0),0)<>"",INDEX(keycodes!$E:$E,MATCH(D15,keycodes!$A:$A,0),0),INDEX(keycodes!$C:$C,MATCH(D15,keycodes!$A:$A,0),0)),INDEX(keycodes!$C:$C,MATCH(D15,keycodes!$B:$B,0),0))) -> KC_W | E41: =IF(E15="",keycodes!$C$2,IF($B$1="Japanese",IF(INDEX(keycodes!$E:$E,MATCH(E15,keycodes!$A:$A,0),0)<>"",INDEX(keycodes!$E:$E,MATCH(E15,keycodes!$A:$A,0),0),INDEX(keycodes!$C:$C,MATCH(E15,keycodes!$A:$A,0),0)),INDEX(keycodes!$C:$C,MATCH(E15,keycodes!$B:$B,0),0))) -> KC_E | F41: =IF(F15="",keycodes!$C$2,IF($B$1="Japanese",IF(INDEX(keycodes!$E:$E,MATCH(F15,keycodes!$A:$A,0),0)<>"",INDEX(keycodes!$E:$E,MATCH(F15,keycodes!$A:$A,0),0),INDEX(keycodes!$C:$C,MATCH(F15,keycodes!$A:$A,0),0)),INDEX(keycodes!$C:$C,MATCH(F15,keycodes!$B:$B,0),0))) -> KC_R | G41: =IF(G15="",keycodes!$C$2,IF($B$1="Japanese",IF(INDEX(keycodes!$E:$E,MATCH(G15,keycodes!$A:$A,0),0)<>"",INDEX(keycodes!$E:$E,MATCH(G15,keycodes!$A:$A,0),0),INDEX(keycodes!$C:$C,MATCH(G15,keycodes!$A:$A,0),0)),INDEX(keycodes!$C:$C,MATCH(G15,keycodes!$B:$B,0),0))) -> KC_T | H41: =IF(H15="",keycodes!$C$2,IF($B$1="Japanese",IF(INDEX(keycodes!$E:$E,MATCH(H15,keycodes!$A:$A,0),0)<>"",INDEX(keycodes!$E:$E,MATCH(H15,keycodes!$A:$A,0),0),INDEX(keycodes!$C:$C,MATCH(H15,keycodes!$A:$A,0),0)),INDEX(keycodes!$C:$C,MATCH(H15,keycodes!$B:$B,0),0))) -> NONE | I41: =IF(I15="",keycodes!$C$2,IF($B$1="Japanese",IF(INDEX(keycodes!$E:$E,MATCH(I15,keycodes!$A:$A,0),0)<>"",INDEX(keycodes!$E:$E,MATCH(I15,keycodes!$A:$A,0),0),INDEX(keycodes!$C:$C,MATCH(I15,keycodes!$A:$A,0),0)),INDEX(keycodes!$C:$C,MATCH(I15,keycodes!$B:$B,0),0))) -> NONE | ... O41: =IF(O15="",keycodes!$C$2,IF($B$1="Japanese",IF(INDEX(keycodes!$E:$E,MATCH(O15,keycodes!$A:$A,0),0)<>"",INDEX(keycodes!$E:$E,MATCH(O15,keycodes!$A:$A,0),0),INDEX(keycodes!$C:$C,MATCH(O15,keycodes!$A:$A,0),0)),INDEX(keycodes!$C:$C,MATCH(O15,keycodes!$B:$B,0),0))) -> KC_LBRC
B42: =IF(B16="",keycodes!$C$2,IF($B$1="Japanese",IF(INDEX(keycodes!$E:$E,MATCH(B16,keycodes!$A:$A,0),0)<>"",INDEX(keycodes!$E:$E,MATCH(B16,keycodes!$A:$A,0),0),INDEX(keycodes!$C:$C,MATCH(B16,keycodes!$A:$A,0),0)),INDEX(keycodes!$C:$C,MATCH(B16,keycodes!$B:$B,0),0))) -> KC_TAB | C42: =IF(C16="",keycodes!$C$2,IF($B$1="Japanese",IF(INDEX(keycodes!$E:$E,MATCH(C16,keycodes!$A:$A,0),0)<>"",INDEX(keycodes!$E:$E,MATCH(C16,keycodes!$A:$A,0),0),INDEX(keycodes!$C:$C,MATCH(C16,keycodes!$A:$A,0),0)),INDEX(keycodes!$C:$C,MATCH(C16,keycodes!$B:$B,0),0))) -> KC_A | D42: =IF(D16="",keycodes!$C$2,IF($B$1="Japanese",IF(INDEX(keycodes!$E:$E,MATCH(D16,keycodes!$A:$A,0),0)<>"",INDEX(keycodes!$E:$E,MATCH(D16,keycodes!$A:$A,0),0),INDEX(keycodes!$C:$C,MATCH(D16,keycodes!$A:$A,0),0)),INDEX(keycodes!$C:$C,MATCH(D16,keycodes!$B:$B,0),0))) -> KC_S | E42: =IF(E16="",keycodes!$C$2,IF($B$1="Japanese",IF(INDEX(keycodes!$E:$E,MATCH(E16,keycodes!$A:$A,0),0)<>"",INDEX(keycodes!$E:$E,MATCH(E16,keycodes!$A:$A,0),0),INDEX(keycodes!$C:$C,MATCH(E16,keycodes!$A:$A,0),0)),INDEX(keycodes!$C:$C,MATCH(E16,keycodes!$B:$B,0),0))) -> KC_D | F42: =IF(F16="",keycodes!$C$2,IF($B$1="Japanese",IF(INDEX(keycodes!$E:$E,MATCH(F16,keycodes!$A:$A,0),0)<>"",INDEX(keycodes!$E:$E,MATCH(F16,keycodes!$A:$A,0),0),INDEX(keycodes!$C:$C,MATCH(F16,keycodes!$A:$A,0),0)),INDEX(keycodes!$C:$C,MATCH(F16,keycodes!$B:$B,0),0))) -> KC_F | G42: =IF(G16="",keycodes!$C$2,IF($B$1="Japanese",IF(INDEX(keycodes!$E:$E,MATCH(G16,keycodes!$A:$A,0),0)<>"",INDEX(keycodes!$E:$E,MATCH(G16,keycodes!$A:$A,0),0),INDEX(keycodes!$C:$C,MATCH(G16,keycodes!$A:$A,0),0)),INDEX(keycodes!$C:$C,MATCH(G16,keycodes!$B:$B,0),0))) -> KC_G | H42: =IF(H16="",keycodes!$C$2,IF($B$1="Japanese",IF(INDEX(keycodes!$E:$E,MATCH(H16,keycodes!$A:$A,0),0)<>"",INDEX(keycodes!$E:$E,MATCH(H16,keycodes!$A:$A,0),0),INDEX(keycodes!$C:$C,MATCH(H16,keycodes!$A:$A,0),0)),INDEX(keycodes!$C:$C,MATCH(H16,keycodes!$B:$B,0),0))) -> NONE | I42: =IF(I16="",keycodes!$C$2,IF($B$1="Japanese",IF(INDEX(keycodes!$E:$E,MATCH(I16,keycodes!$A:$A,0),0)<>"",INDEX(keycodes!$E:$E,MATCH(I16,keycodes!$A:$A,0),0),INDEX(keycodes!$C:$C,MATCH(I16,keycodes!$A:$A,0),0)),INDEX(keycodes!$C:$C,MATCH(I16,keycodes!$B:$B,0),0))) -> NONE | ... O42: =IF(O16="",keycodes!$C$2,IF($B$1="Japanese",IF(INDEX(keycodes!$E:$E,MATCH(O16,keycodes!$A:$A,0),0)<>"",INDEX(keycodes!$E:$E,MATCH(O16,keycodes!$A:$A,0),0),INDEX(keycodes!$C:$C,MATCH(O16,keycodes!$A:$A,0),0)),INDEX(keycodes!$C:$C,MATCH(O16,keycodes!$B:$B,0),0))) -> KC_QUOT
B43: =IF(B17="",keycodes!$C$2,IF($B$1="Japanese",IF(INDEX(keycodes!$E:$E,MATCH(B17,keycodes!$A:$A,0),0)<>"",INDEX(keycodes!$E:$E,MATCH(B17,keycodes!$A:$A,0),0),INDEX(keycodes!$C:$C,MATCH(B17,keycodes!$A:$A,0),0)),INDEX(keycodes!$C:$C,MATCH(B17,keycodes!$B:$B,0),0))) -> _______ | C43: =IF(C17="",keycodes!$C$2,IF($B$1="Japanese",IF(INDEX(keycodes!$E:$E,MATCH(C17,keycodes!$A:$A,0),0)<>"",INDEX(keycodes!$E:$E,MATCH(C17,keycodes!$A:$A,0),0),INDEX(keycodes!$C:$C,MATCH(C17,keycodes!$A:$A,0),0)),INDEX(keycodes!$C:$C,MATCH(C17,keycodes!$B:$B,0),0))) -> KC_Z | D43: =IF(D17="",keycodes!$C$2,IF($B$1="Japanese",IF(INDEX(keycodes!$E:$E,MATCH(D17,keycodes!$A:$A,0),0)<>"",INDEX(keycodes!$E:$E,MATCH(D17,keycodes!$A:$A,0),0),INDEX(keycodes!$C:$C,MATCH(D17,keycodes!$A:$A,0),0)),INDEX(keycodes!$C:$C,MATCH(D17,keycodes!$B:$B,0),0))) -> KC_X | E43: =IF(E17="",keycodes!$C$2,IF($B$1="Japanese",IF(INDEX(keycodes!$E:$E,MATCH(E17,keycodes!$A:$A,0),0)<>"",INDEX(keycodes!$E:$E,MATCH(E17,keycodes!$A:$A,0),0),INDEX(keycodes!$C:$C,MATCH(E17,keycodes!$A:$A,0),0)),INDEX(keycodes!$C:$C,MATCH(E17,keycodes!$B:$B,0),0))) -> KC_C | F43: =IF(F17="",keycodes!$C$2,IF($B$1="Japanese",IF(INDEX(keycodes!$E:$E,MATCH(F17,keycodes!$A:$A,0),0)<>"",INDEX(keycodes!$E:$E,MATCH(F17,keycodes!$A:$A,0),0),INDEX(keycodes!$C:$C,MATCH(F17,keycodes!$A:$A,0),0)),INDEX(keycodes!$C:$C,MATCH(F17,keycodes!$B:$B,0),0))) -> KC_V | G43: =IF(G17="",keycodes!$C$2,IF($B$1="Japanese",IF(INDEX(keycodes!$E:$E,MATCH(G17,keycodes!$A:$A,0),0)<>"",INDEX(keycodes!$E:$E,MATCH(G17,keycodes!$A:$A,0),0),INDEX(keycodes!$C:$C,MATCH(G17,keycodes!$A:$A,0),0)),INDEX(keycodes!$C:$C,MATCH(G17,keycodes!$B:$B,0),0))) -> KC_B | H43: =IF(H17="",keycodes!$C$2,IF($B$1="Japanese",IF(INDEX(keycodes!$E:$E,MATCH(H17,keycodes!$A:$A,0),0)<>"",INDEX(keycodes!$E:$E,MATCH(H17,keycodes!$A:$A,0),0),INDEX(keycodes!$C:$C,MATCH(H17,keycodes!$A:$A,0),0)),INDEX(keycodes!$C:$C,MATCH(H17,keycodes!$B:$B,0),0))) -> NONE | I43: =IF(I17="",keycodes!$C$2,IF($B$1="Japanese",IF(INDEX(keycodes!$E:$E,MATCH(I17,keycodes!$A:$A,0),0)<>"",INDEX(keycodes!$E:$E,MATCH(I17,keycodes!$A:$A,0),0),INDEX(keycodes!$C:$C,MATCH(I17,keycodes!$A:$A,0),0)),INDEX(keycodes!$C:$C,MATCH(I17,keycodes!$B:$B,0),0))) -> NONE | ... O43: =IF(O17="",keycodes!$C$2,IF($B$1="Japanese",IF(INDEX(keycodes!$E:$E,MATCH(O17,keycodes!$A:$A,0),0)<>"",INDEX(keycodes!$E:$E,MATCH(O17,keycodes!$A:$A,0),0),INDEX(keycodes!$C:$C,MATCH(O17,keycodes!$A:$A,0),0)),INDEX(keycodes!$C:$C,MATCH(O17,keycodes!$B:$B,0),0))) -> _______
...
