Workbook

Sheet keycodes
A1: 日本語キー | B1: 英語キー | C1: キーコード | D1: 備考 | E1: キーコードエイリアス
A2: NOOP | B2: NOOP | C2: XXXXXXX
A3: Transparent | B3: Transparent | C3: _______
A4: A | B4: A | C4: KC_A
A5: B | B5: B | C5: KC_B
A6: C | B6: C | C6: KC_C
A7: D | B7: D | C7: KC_D
A8: E | B8: E | C8: KC_E
A9: F | B9: F | C9: KC_F
A10: G | B10: G | C10: KC_G
A11: H | B11: H | C11: KC_H
A12: I | B12: I | C12: KC_I
A13: J | B13: J | C13: KC_J
... A29: Z | B29: Z | C29: KC_Z
A30: 1 | B30: 1 | C30: KC_1
A31: 2 | B31: 2 | C31: KC_2
A32: 3 | B32: 3 | C32: KC_3
A33: 4 | B33: 4 | C33: KC_4
A34: 5 | B34: 5 | C34: KC_5
A35: 6 | B35: 6 | C35: KC_6
A36: 7 | B36: 7 | C36: KC_7
A37: 8 | B37: 8 | C37: KC_8
A38: 9 | B38: 9 | C38: KC_9
A39: 0 | B39: 0 | C39: KC_0
A40: F1 | B40: F1 | C40: KC_F1
A41: F2 | B41: F2 | C41: KC_F2
A42: F3 | B42: F3 | C42: KC_F3
A43: F4 | B43: F4 | C43: KC_F4
A44: F5 | B44: F5 | C44: KC_F5
A45: F6 | B45: F6 | C45: KC_F6
A46: F7 | B46: F7 | C46: KC_F7
A47: F8 | B47: F8 | C47: KC_F8
A48: F9 | B48: F9 | C48: KC_F9
A49: F10 | B49: F10 | C49: KC_F10
A50: F11 | B50: F11 | C50: KC_F11
A51: F12 | B51: F12 | C51: KC_F12
... A68: Left Alt | B68: Left Alt | C68: KC_LALT
A69: Left GUI | B69: Left GUI | C69: KC_LGUI | D69: Windows
A70: Right Control | B70: Right Control | C70: KC_RCTL
A71: Right Shift | B71: Right Shift | C71: KC_RSFT
...

Sheet yoc2
B1: Japanese
A3: DEFAULT | B3: Esc | C3: 1 | D3: 2 | E3: 3 | F3: 4 | G3: 5 | H3: NONE | I3: NONE | J3: 6 | K3: 7 | L3: 8 | M3: 9 | N3: 0 | O3: -
B4: Left Alt | C4: Q | D4: W | E4: E | F4: R | G4: T | H4: NONE | I4: NONE | J4: Y | K4: U | L4: I | M4: O | N4: P | O4: @
B5: Tab | C5: A | D5: S | E5: D | F5: F | G5: G | H5: NONE | I5: NONE | J5: H | K5: J | L5: K | M5: L | N5: ; | O5: :
B6: Left Control | C6: Z | D6: X | E6: C | F6: V | G6: B | H6: Backspace | I6: Delete | J6: N | K6: M | L6: , | M6: . | N6: / | O6: \
B7: NONE | C7: NONE | D7: NONE | E7: Left GUI | F7: ToggleRaise | G7: MoRaise | H7: Shift & Space | I7: Shift & Enter | J7: MoLower | K7: ToggleLower | L7: APP | M7: TERM | N7: TERM | O7: TERM
A8: LOWER | B8: Transparent | C8: Transparent | D8: Transparent | E8: Transparent | F8: Transparent | G8: Transparent | H8: NONE | I8: NONE | J8: Transparent | K8: Transparent | L8: Transparent | M8: Transparent | N8: Transparent | O8: Transparent
B9: APP | C9: S ! | D9: S " | E9: S # | F9: S $ | G9: S % | H9: NONE | I9: NONE | J9: S & | K9: S ' | L9: S ( | M9: S )
B10: Left GUI | D10: Home | E10: Page Up | F10: Page Down | G10: End | H10: NONE | I10: NONE | J10: Left Arrow | K10: Down Arrow | L10: Up Arrow | M10: Right Arrow | N10: ^ | O10: -
B11: Transparent | C11: Left Alt | F11: 無変換 | G11: Backspace | H11: Transparent | I11: Transparent | J11: Delete | K11: 変換 | L11: [ | M11: ] | N11: S Tilde | O11: S |
B12: NONE | C12: NONE | D12: NONE | E12: Transparent | F12: Transparent | G12: Transparent | H12: Transparent | I12: Transparent | J12: Transparent | K12: Transparent | L12: Transparent | M12: TERM | N12: TERM | O12: TERM
A13: RAISE | B13: F1 | C13: F2 | D13: F3 | E13: F4 | F13: F5 | G13: F6 | H13: NONE | I13: NONE | J13: F7 | K13: F8 | L13: F9 | M13: F10 | N13: F11 | O13: F12
H14: NONE | I14: NONE
B15: 半角/全角 | C15: 1 | D15: 2 | E15: 3 | F15: 4 | G15: 5 | H15: NONE | I15: NONE | J15: 6 | K15: 7 | L15: 8 | M15: 9 | N15: 0 | O15: Transparent
B16: Transparent | C16: Transparent | D16: Wheel Left | E16: Wheel Right | F16: Transparent | G16: Transparent | H16: Transparent | I16: Transparent | J16: Transparent | K16: Transparent | L16: , | M16: . | N16: / | O16: \
B17: NONE | C17: NONE | D17: NONE | E17: Transparent | F17: Transparent | G17: Transparent | H17: Transparent | I17: Transparent | J17: Transparent | K17: Transparent | L17: Transparent | M17: TERM | N17: TERM | O17: TERM
A18: ADJUST | B18: Esc | C18: 1 | D18: 2 | E18: 3 | F18: 4 | G18: 5 | H18: NONE | I18: NONE | J18: 6 | K18: 7 | L18: 8 | M18: 9 | N18: 0 | O18: -
B19: Tab | C19: Q | D19: W | E19: E | F19: R | G19: T | H19: NONE | I19: NONE | J19: Y | K19: U | L19: I | M19: O | N19: P | O19: @
B20: Left Control | C20: A | D20: S | E20: D | F20: F | G20: G | H20: NONE | I20: NONE | J20: H | K20: J | L20: K | M20: L | N20: ; | O20: :
B21: Left Shift | C21: Z | D21: X | E21: C | F21: V | G21: B | H21: Transparent | I21: Transparent | J21: N | K21: M | L21: Transparent | M21: Transparent | N21: Transparent | O21: Transparent
B22: NONE | C22: NONE | D22: NONE | E22: Transparent | F22: ToggleRaise | G22: Space | H22: MoRaiseAdjust | I22: MoLowerAdjust | J22: Enter | K22: ToggleLower | L22: Transparent | M22: TERM | N22: TERM | O22: TERM
A23: LOWER_ADJUST | B23: Transparent | C23: Transparent | D23: Transparent | E23: Transparent | F23: Transparent | G23: Transparent | H23: NONE | I23: NONE | J23: Transparent | K23: Transparent | L23: Transparent | M23: Transparent | N23: Transparent | O23: Transparent
C24: S ! | D24: S " | E24: S # | F24: S $ | G24: S % | H24: NONE | I24: NONE | J24: S & | K24: S ' | L24: S ( | M24: S )
D25: Home | E25: Page Up | F25: Page Down | G25: End | H25: NONE | I25: NONE | J25: Left Arrow | K25: Down Arrow | L25: Up Arrow | M25: Right Arrow | N25: ^ | O25: -
B26: Left Control | C26: Left Alt | F26: 無変換 | G26: Backspace | H26: Transparent | I26: Transparent | J26: Delete | K26: 変換 | L26: [ | M26: ] | N26: S Tilde | O26: S |
B27: NONE | C27: NONE | D27: NONE | E27: Transparent | F27: Transparent | G27: Transparent | H27: Transparent | I27: Transparent | J27: Transparent | K27: Transparent | L27: Transparent | M27: TERM | N27: TERM | O27: TERM
A28: RAISE_ADJUST | B28: F1 | C28: F2 | D28: F3 | E28: F4 | F28: F5 | G28: F6 | H28: NONE | I28: NONE | J28: F7 | K28: F8 | L28: F9 | M28: F10 | N28: F11 | O28: F12
H29: NONE | I29: NONE
C30: 1 | D30: 2 | E30: 3 | F30: 4 | G30: 5 | H30: NONE | I30: NONE | J30: 6 | K30: 7 | L30: 8 | M30: 9 | N30: 0 | O30: Transparent
B31: Transparent | C31: Transparent | D31: Volume Down | E31: Volume Up | F31: Transparent | G31: Transparent | H31: Transparent | I31: Transparent | J31: Transparent | K31: Transparent | L31: , | M31: . | N31: / | O31: \
B32: NONE | C32: NONE | D32: NONE | E32: Transparent | F32: Transparent | G32: Transparent | H32: Transparent | I32: Transparent | J32: Transparent | K32: Transparent | L32: Transparent | M32: TERM | N32: TERM | O32: TERM
A35: DEFAULT | B35: =IF(B3="",keycodes!$C$2,IF($B$1="Japanese",IF(INDEX(keycodes!$E:$E,MATCH(B3,keycodes!$A:$A,0),0)<>"",INDEX(keycodes!$E:$E,MATCH(B3,keycodes!$A:$A,0),0),INDEX(keycodes!$C:$C,MATCH(B3,keycodes!$A:$A,0),0)),INDEX(keycodes!$C:$C,MATCH(B3,keycodes!$B:$B,0),0))) -> KC_ESC | C35: =IF(C3="",keycodes!$C$2,IF($B$1="Japanese",IF(INDEX(keycodes!$E:$E,MATCH(C3,keycodes!$A:$A,0),0)<>"",INDEX(keycodes!$E:$E,MATCH(C3,keycodes!$A:$A,0),0),INDEX(keycodes!$C:$C,MATCH(C3,keycodes!$A:$A,0),0)),INDEX(keycodes!$C:$C,MATCH(C3,keycodes!$B:$B,0),0))) -> KC_1 | D35: =IF(D3="",keycodes!$C$2,IF($B$1="Japanese",IF(INDEX(keycodes!$E:$E,MATCH(D3,keycodes!$A:$A,0),0)<>"",INDEX(keycodes!$E:$E,MATCH(D3,keycodes!$A:$A,0),0),INDEX(keycodes!$C:$C,MATCH(D3,keycodes!$A:$A,0),0)),INDEX(keycodes!$C:$C,MATCH(D3,keycodes!$B:$B,0),0))) -> KC_2 | E35: =IF(E3="",keycodes!$C$2,IF($B$1="Japanese",IF(INDEX(keycodes!$E:$E,MATCH(E3,keycodes!$A:$A,0),0)<>"",INDEX(keycodes!$E:$E,MATCH(E3,keycodes!$A:$A,0),0),INDEX(keycodes!$C:$C,MATCH(E3,keycodes!$A:$A,0),0)),INDEX(keycodes!$C:$C,MATCH(E3,keycodes!$B:$B,0),0))) -> KC_3 | F35: =IF(F3="",keycodes!$C$2,IF($B$1="Japanese",IF(INDEX(keycodes!$E:$E,MATCH(F3,keycodes!$A:$A,0),0)<>"",INDEX(keycodes!$E:$E,MATCH(F3,keycodes!$A:$A,0),0),INDEX(keycodes!$C:$C,MATCH(F3,keycodes!$A:$A,0),0)),INDEX(keycodes!$C:$C,MATCH(F3,keycodes!$B:$B,0),0))) -> KC_4 | G35: =IF(G3="",keycodes!$C$2,IF($B$1="Japanese",IF(INDEX(keycodes!$E:$E,MATCH(G3,keycodes!$A:$A,0),0)<>"",INDEX(keycodes!$E:$E,MATCH(G3,keycodes!$A:$A,0),0),INDEX(keycodes!$C:$C,MATCH(G3,keycodes!$A:$A,0),0)),INDEX(keycodes!$C:$C,MATCH(G3,keycodes!$B:$B,0),0))) -> KC_5 | H35: =IF(H3="",keycodes!$C$2,IF($B$1="Japanese",IF(INDEX(keycodes!$E:$E,MATCH(H3,keycodes!$A:$A,0),0)<>"",INDEX(keycodes!$E:$E,MATCH(H3,keycodes!$A:$A,0),0),INDEX(keycodes!$C:$C,MATCH(H3,keycodes!$A:$A,0),0)),INDEX(keycodes!$C:$C,MATCH(H3,keycodes!$B:$B,0),0))) -> NONE | I35: =IF(I3="",keycodes!$C$2,IF($B$1="Japanese",IF(INDEX(keycodes!$E:$E,MATCH(I3,keycodes!$A:$A,0),0)<>"",INDEX(keycodes!$E:$E,MATCH(I3,keycodes!$A:$A,0),0),INDEX(keycodes!$C:$C,MATCH(I3,keycodes!$A:$A,0),0)),INDEX(keycodes!$C:$C,MATCH(I3,keycodes!$B:$B,0),0))) -> NONE | ... O35: =IF(O3="",keycodes!$C$2,IF($B$1="Japanese",IF(INDEX(keycodes!$E:$E,MATCH(O3,keycodes!$A:$A,0),0)<>"",INDEX(keycodes!$E:$E,MATCH(O3,keycodes!$A:$A,0),0),INDEX(keycodes!$C:$C,MATCH(O3,keycodes!$A:$A,0),0)),INDEX(keycodes!$C:$C,MATCH(O3,keycodes!$B:$B,0),0))) -> KC_MINS
B36: =IF(B4="",keycodes!$C$2,IF($B$1="Japanese",IF(INDEX(keycodes!$E:$E,MATCH(B4,keycodes!$A:$A,0),0)<>"",INDEX(keycodes!$E:$E,MATCH(B4,keycodes!$A:$A,0),0),INDEX(keycodes!$C:$C,MATCH(B4,keycodes!$A:$A,0),0)),INDEX(keycodes!$C:$C,MATCH(B4,keycodes!$B:$B,0),0))) -> KC_LALT | C36: =IF(C4="",keycodes!$C$2,IF($B$1="Japanese",IF(INDEX(keycodes!$E:$E,MATCH(C4,keycodes!$A:$A,0),0)<>"",INDEX(keycodes!$E:$E,MATCH(C4,keycodes!$A:$A,0),0),INDEX(keycodes!$C:$C,MATCH(C4,keycodes!$A:$A,0),0)),INDEX(keycodes!$C:$C,MATCH(C4,keycodes!$B:$B,0),0))) -> KC_Q | D36: =IF(D4="",keycodes!$C$2,IF($B$1="Japanese",IF(INDEX(keycodes!$E:$E,MATCH(D4,keycodes!$A:$A,0),0)<>"",INDEX(keycodes!$E:$E,MATCH(D4,keycodes!$A:$A,0),0),INDEX(keycodes!$C:$C,MATCH(D4,keycodes!$A:$A,0),0)),INDEX(keycodes!$C:$C,MATCH(D4,keycodes!$B:$B,0),0))) -> KC_W | E36: =IF(E4="",keycodes!$C$2,IF($B$1="Japanese",IF(INDEX(keycodes!$E:$E,MATCH(E4,keycodes!$A:$A,0),0)<>"",INDEX(keycodes!$E:$E,MATCH(E4,keycodes!$A:$A,0),0),INDEX(keycodes!$C:$C,MATCH(E4,keycodes!$A:$A,0),0)),INDEX(keycodes!$C:$C,MATCH(E4,keycodes!$B:$B,0),0))) -> KC_E | F36: =IF(F4="",keycodes!$C$2,IF($B$1="Japanese",IF(INDEX(keycodes!$E:$E,MATCH(F4,keycodes!$A:$A,0),0)<>"",INDEX(keycodes!$E:$E,MATCH(F4,keycodes!$A:$A,0),0),INDEX(keycodes!$C:$C,MATCH(F4,keycodes!$A:$A,0),0)),INDEX(keycodes!$C:$C,MATCH(F4,keycodes!$B:$B,0),0))) -> KC_R | G36: =IF(G4="",keycodes!$C$2,IF($B$1="Japanese",IF(INDEX(keycodes!$E:$E,MATCH(G4,keycodes!$A:$A,0),0)<>"",INDEX(keycodes!$E:$E,MATCH(G4,keycodes!$A:$A,0),0),INDEX(keycodes!$C:$C,MATCH(G4,keycodes!$A:$A,0),0)),INDEX(keycodes!$C:$C,MATCH(G4,keycodes!$B:$B,0),0))) -> KC_T | H36: =IF(H4="",keycodes!$C$2,IF($B$1="Japanese",IF(INDEX(keycodes!$E:$E,MATCH(H4,keycodes!$A:$A,0),0)<>"",INDEX(keycodes!$E:$E,MATCH(H4,keycodes!$A:$A,0),0),INDEX(keycodes!$C:$C,MATCH(H4,keycodes!$A:$A,0),0)),INDEX(keycodes!$C:$C,MATCH(H4,keycodes!$B:$B,0),0))) -> NONE | I36: =IF(I4="",keycodes!$C$2,IF($B$1="Japanese",IF(INDEX(keycodes!$E:$E,MATCH(I4,keycodes!$A:$A,0),0)<>"",INDEX(keycodes!$E:$E,MATCH(I4,keycodes!$A:$A,0),0),INDEX(keycodes!$C:$C,MATCH(I4,keycodes!$A:$A,0),0)),INDEX(keycodes!$C:$C,MATCH(I4,keycodes!$B:$B,0),0))) -> NONE | ... O36: =IF(O4="",keycodes!$C$2,IF($B$1="Japanese",IF(INDEX(keycodes!$E:$E,MATCH(O4,keycodes!$A:$A,0),0)<>"",INDEX(keycodes!$E:$E,MATCH(O4,keycodes!$A:$A,0),0),INDEX(keycodes!$C:$C,MATCH(O4,keycodes!$A:$A,0),0)),INDEX(keycodes!$C:$C,MATCH(O4,keycodes!$B:$B,0),0))) -> KC_LBRC
B37: =IF(B5="",keycodes!$C$2,IF($B$1="Japanese",IF(INDEX(keycodes!$E:$E,MATCH(B5,keycodes!$A:$A,0),0)<>"",INDEX(keycodes!$E:$E,MATCH(B5,keycodes!$A:$A,0),0),INDEX(keycodes!$C:$C,MATCH(B5,keycodes!$A:$A,0),0)),INDEX(keycodes!$C:$C,MATCH(B5,keycodes!$B:$B,0),0))) -> KC_TAB | C37: =IF(C5="",keycodes!$C$2,IF($B$1="Japanese",IF(INDEX(keycodes!$E:$E,MATCH(C5,keycodes!$A:$A,0),0)<>"",INDEX(keycodes!$E:$E,MATCH(C5,keycodes!$A:$A,0),0),INDEX(keycodes!$C:$C,MATCH(C5,keycodes!$A:$A,0),0)),INDEX(keycodes!$C:$C,MATCH(C5,keycodes!$B:$B,0),0))) -> KC_A | D37: =IF(D5="",keycodes!$C$2,IF($B$1="Japanese",IF(INDEX(keycodes!$E:$E,MATCH(D5,keycodes!$A:$A,0),0)<>"",INDEX(keycodes!$E:$E,MATCH(D5,keycodes!$A:$A,0),0),INDEX(keycodes!$C:$C,MATCH(D5,keycodes!$A:$A,0),0)),INDEX(keycodes!$C:$C,MATCH(D5,keycodes!$B:$B,0),0))) -> KC_S | E37: =IF(E5="",keycodes!$C$2,IF($B$1="Japanese",IF(INDEX(keycodes!$E:$E,MATCH(E5,keycodes!$A:$A,0),0)<>"",INDEX(keycodes!$E:$E,MATCH(E5,keycodes!$A:$A,0),0),INDEX(keycodes!$C:$C,MATCH(E5,keycodes!$A:$A,0),0)),INDEX(keycodes!$C:$C,MATCH(E5,keycodes!$B:$B,0),0))) -> KC_D | F37: =IF(F5="",keycodes!$C$2,IF($B$1="Japanese",IF(INDEX(keycodes!$E:$E,MATCH(F5,keycodes!$A:$A,0),0)<>"",INDEX(keycodes!$E:$E,MATCH(F5,keycodes!$A:$A,0),0),INDEX(keycodes!$C:$C,MATCH(F5,keycodes!$A:$A,0),0)),INDEX(keycodes!$C:$C,MATCH(F5,keycodes!$B:$B,0),0))) -> KC_F | G37: =IF(G5="",keycodes!$C$2,IF($B$1="Japanese",IF(INDEX(keycodes!$E:$E,MATCH(G5,keycodes!$A:$A,0),0)<>"",INDEX(keycodes!$E:$E,MATCH(G5,keycodes!$A:$A,0),0),INDEX(keycodes!$C:$C,MATCH(G5,keycodes!$A:$A,0),0)),INDEX(keycodes!$C:$C,MATCH(G5,keycodes!$B:$B,0),0))) -> KC_G | H37: =IF(H5="",keycodes!$C$2,IF($B$1="Japanese",IF(INDEX(keycodes!$E:$E,MATCH(H5,keycodes!$A:$A,0),0)<>"",INDEX(keycodes!$E:$E,MATCH(H5,keycodes!$A:$A,0),0),INDEX(keycodes!$C:$C,MATCH(H5,keycodes!$A:$A,0),0)),INDEX(keycodes!$C:$C,MATCH(H5,keycodes!$B:$B,0),0))) -> NONE | I37: =IF(I5="",keycodes!$C$2,IF($B$1="Japanese",IF(INDEX(keycodes!$E:$E,MATCH(I5,keycodes!$A:$A,0),0)<>"",INDEX(keycodes!$E:$E,MATCH(I5,keycodes!$A:$A,0),0),INDEX(keycodes!$C:$C,MATCH(I5,keycodes!$A:$A,0),0)),INDEX(keycodes!$C:$C,MATCH(I5,keycodes!$B:$B,0),0))) -> NONE | ... O37: =IF(O5="",keycodes!$C$2,IF($B$1="Japanese",IF(INDEX(keycodes!$E:$E,MATCH(O5,keycodes!$A:$A,0),0)<>"",INDEX(keycodes!$E:$E,MATCH(O5,keycodes!$A:$A,0),0),INDEX(keycodes!$C:$C,MATCH(O5,keycodes!$A:$A,0),0)),INDEX(keycodes!$C:$C,MATCH(O5,keycodes!$B:$B,0),0))) -> KC_QUOT
B38: =IF(B6="",keycodes!$C$2,IF($B$1="Japanese",IF(INDEX(keycodes!$E:$E,MATCH(B6,keycodes!$A:$A,0),0)<>"",INDEX(keycodes!$E:$E,MATCH(B6,keycodes!$A:$A,0),0),INDEX(keycodes!$C:$C,MATCH(B6,keycodes!$A:$A,0),0)),INDEX(keycodes!$C:$C,MATCH(B6,keycodes!$B:$B,0),0))) -> KC_LCTL | C38: =IF(C6="",keycodes!$C$2,IF($B$1="Japanese",IF(INDEX(keycodes!$E:$E,MATCH(C6,keycodes!$A:$A,0),0)<>"",INDEX(keycodes!$E:$E,MATCH(C6,keycodes!$A:$A,0),0),INDEX(keycodes!$C:$C,MATCH(C6,keycodes!$A:$A,0),0)),INDEX(keycodes!$C:$C,MATCH(C6,keycodes!$B:$B,0),0))) -> KC_Z | D38: =IF(D6="",keycodes!$C$2,IF($B$1="Japanese",IF(INDEX(keycodes!$E:$E,MATCH(D6,keycodes!$A:$A,0),0)<>"",INDEX(keycodes!$E:$E,MATCH(D6,keycodes!$A:$A,0),0),INDEX(keycodes!$C:$C,MATCH(D6,keycodes!$A:$A,0),0)),INDEX(keycodes!$C:$C,MATCH(D6,keycodes!$B:$B,0),0))) -> KC_X | E38: =IF(E6="",keycodes!$C$2,IF($B$1="Japanese",IF(INDEX(keycodes!$E:$E,MATCH(E6,keycodes!$A:$A,0),0)<>"",INDEX(keycodes!$E:$E,MATCH(E6,keycodes!$A:$A,0),0),INDEX(keycodes!$C:$C,MATCH(E6,keycodes!$A:$A,0),0)),INDEX(keycodes!$C:$C,MATCH(E6,keycodes!$B:$B,0),0))) -> KC_C | F38: =IF(F6="",keycodes!$C$2,IF($B$1="Japanese",IF(INDEX(keycodes!$E:$E,MATCH(F6,keycodes!$A:$A,0),0)<>"",INDEX(keycodes!$E:$E,MATCH(F6,keycodes!$A:$A,0),0),INDEX(keycodes!$C:$C,MATCH(F6,keycodes!$A:$A,0),0)),INDEX(keycodes!$C:$C,MATCH(F6,keycodes!$B:$B,0),0))) -> KC_V | G38: =IF(G6="",keycodes!$C$2,IF($B$1="Japanese",IF(INDEX(keycodes!$E:$E,MATCH(G6,keycodes!$A:$A,0),0)<>"",INDEX(keycodes!$E:$E,MATCH(G6,keycodes!$A:$A,0),0),INDEX(keycodes!$C:$C,MATCH(G6,keycodes!$A:$A,0),0)),INDEX(keycodes!$C:$C,MATCH(G6,keycodes!$B:$B,0),0))) -> KC_B | H38: =IF(H6="",keycodes!$C$2,IF($B$1="Japanese",IF(INDEX(keycodes!$E:$E,MATCH(H6,keycodes!$A:$A,0),0)<>"",INDEX(keycodes!$E:$E,MATCH(H6,keycodes!$A:$A,0),0),INDEX(keycodes!$C:$C,MATCH(H6,keycodes!$A:$A,0),0)),INDEX(keycodes!$C:$C,MATCH(H6,keycodes!$B:$B,0),0))) -> KC_BSPC | I38: =IF(I6="",keycodes!$C$2,IF($B$1="Japanese",IF(INDEX(keycodes!$E:$E,MATCH(I6,keycodes!$A:$A,0),0)<>"",INDEX(keycodes!$E:$E,MATCH(I6,keycodes!$A:$A,0),0),INDEX(keycodes!$C:$C,MATCH(I6,keycodes!$A:$A,0),0)),INDEX(keycodes!$C:$C,MATCH(I6,keycodes!$B:$B,0),0))) -> KC_DEL | ... O38: =IF(O6="",keycodes!$C$2,IF($B$1="Japanese",IF(INDEX(keycodes!$E:$E,MATCH(O6,keycodes!$A:$A,0),0)<>"",INDEX(keycodes!$E:$E,MATCH(O6,keycodes!$A:$A,0),0),INDEX(keycodes!$C:$C,MATCH(O6,keycodes!$A:$A,0),0)),INDEX(keycodes!$C:$C,MATCH(O6,keycodes!$B:$B,0),0))) -> KC_INT1
B39: =IF(B7="",keycodes!$C$2,IF($B$1="Japanese",IF(INDEX(keycodes!$E:$E,MATCH(B7,keycodes!$A:$A,0),0)<>"",INDEX(keycodes!$E:$E,MATCH(B7,keycodes!$A:$A,0),0),INDEX(keycodes!$C:$C,MATCH(B7,keycodes!$A:$A,0),0)),INDEX(keycodes!$C:$C,MATCH(B7,keycodes!$B:$B,0),0))) -> NONE | C39: =IF(C7="",keycodes!$C$2,IF($B$1="Japanese",IF(INDEX(keycodes!$E:$E,MATCH(C7,keycodes!$A:$A,0),0)<>"",INDEX(keycodes!$E:$E,MATCH(C7,keycodes!$A:$A,0),0),INDEX(keycodes!$C:$C,MATCH(C7,keycodes!$A:$A,0),0)),INDEX(keycodes!$C:$C,MATCH(C7,keycodes!$B:$B,0),0))) -> NONE | D39: =IF(D7="",keycodes!$C$2,IF($B$1="Japanese",IF(INDEX(keycodes!$E:$E,MATCH(D7,keycodes!$A:$A,0),0)<>"",INDEX(keycodes!$E:$E,MATCH(D7,keycodes!$A:$A,0),0),INDEX(keycodes!$C:$C,MATCH(D7,keycodes!$A:$A,0),0)),INDEX(keycodes!$C:$C,MATCH(D7,keycodes!$B:$B,0),0))) -> NONE | E39: =IF(E7="",keycodes!$C$2,IF($B$1="Japanese",IF(INDEX(keycodes!$E:$E,MATCH(E7,keycodes!$A:$A,0),0)<>"",INDEX(keycodes!$E:$E,MATCH(E7,keycodes!$A:$A,0),0),INDEX(keycodes!$C:$C,MATCH(E7,keycodes!$A:$A,0),0)),INDEX(keycodes!$C:$C,MATCH(E7,keycodes!$B:$B,0),0))) -> KC_LGUI | F39: =IF(F7="",keycodes!$C$2,IF($B$1="Japanese",IF(INDEX(keycodes!$E:$E,MATCH(F7,keycodes!$A:$A,0),0)<>"",INDEX(keycodes!$E:$E,MATCH(F7,keycodes!$A:$A,0),0),INDEX(keycodes!$C:$C,MATCH(F7,keycodes!$A:$A,0),0)),INDEX(keycodes!$C:$C,MATCH(F7,keycodes!$B:$B,0),0))) -> TG_R | G39: =IF(G7="",keycodes!$C$2,IF($B$1="Japanese",IF(INDEX(keycodes!$E:$E,MATCH(G7,keycodes!$A:$A,0),0)<>"",INDEX(keycodes!$E:$E,MATCH(G7,keycodes!$A:$A,0),0),INDEX(keycodes!$C:$C,MATCH(G7,keycodes!$A:$A,0),0)),INDEX(keycodes!$C:$C,MATCH(G7,keycodes!$B:$B,0),0))) -> MO_R | H39: =IF(H7="",keycodes!$C$2,IF($B$1="Japanese",IF(INDEX(keycodes!$E:$E,MATCH(H7,keycodes!$A:$A,0),0)<>"",INDEX(keycodes!$E:$E,MATCH(H7,keycodes!$A:$A,0),0),INDEX(keycodes!$C:$C,MATCH(H7,keycodes!$A:$A,0),0)),INDEX(keycodes!$C:$C,MATCH(H7,keycodes!$B:$B,0),0))) -> LSFT_SPC | I39: =IF(I7="",keycodes!$C$2,IF($B$1="Japanese",IF(INDEX(keycodes!$E:$E,MATCH(I7,keycodes!$A:$A,0),0)<>"",INDEX(keycodes!$E:$E,MATCH(I7,keycodes!$A:$A,0),0),INDEX(keycodes!$C:$C,MATCH(I7,keycodes!$A:$A,0),0)),INDEX(keycodes!$C:$C,MATCH(I7,keycodes!$B:$B,0),0))) -> RSTF_ENT | ... O39: =IF(O7="",keycodes!$C$2,IF($B$1="Japanese",IF(INDEX(keycodes!$E:$E,MATCH(O7,keycodes!$A:$A,0),0)<>"",INDEX(keycodes!$E:$E,MATCH(O7,keycodes!$A:$A,0),0),INDEX(keycodes!$C:$C,MATCH(O7,keycodes!$A:$A,0),0)),INDEX(keycodes!$C:$C,MATCH(O7,keycodes!$B:$B,0),0))) -> TERM
A40: LOWER | B40: =IF(B8="",keycodes!$C$2,IF($B$1="Japanese",IF(INDEX(keycodes!$E:$E,MATCH(B8,keycodes!$A:$A,0),0)<>"",INDEX(keycodes!$E:$E,MATCH(B8,keycodes!$A:$A,0),0),INDEX(keycodes!$C:$C,MATCH(B8,keycodes!$A:$A,0),0)),INDEX(keycodes!$C:$C,MATCH(B8,keycodes!$B:$B,0),0))) -> _______ | C40: =IF(C8="",keycodes!$C$2,IF($B$1="Japanese",IF(INDEX(keycodes!$E:$E,MATCH(C8,keycodes!$A:$A,0),0)<>"",INDEX(keycodes!$E:$E,MATCH(C8,keycodes!$A:$A,0),0),INDEX(keycodes!$C:$C,MATCH(C8,keycodes!$A:$A,0),0)),INDEX(keycodes!$C:$C,MATCH(C8,keycodes!$B:$B,0),0))) -> _______ | D40: =IF(D8="",keycodes!$C$2,IF($B$1="Japanese",IF(INDEX(keycodes!$E:$E,MATCH(D8,keycodes!$A:$A,0),0)<>"",INDEX(keycodes!$E:$E,MATCH(D8,keycodes!$A:$A,0),0),INDEX(keycodes!$C:$C,MATCH(D8,keycodes!$A:$A,0),0)),INDEX(keycodes!$C:$C,MATCH(D8,keycodes!$B:$B,0),0))) -> _______ | E40: =IF(E8="",keycodes!$C$2,IF($B$1="Japanese",IF(INDEX(keycodes!$E:$E,MATCH(E8,keycodes!$A:$A,0),0)<>"",INDEX(keycodes!$E:$E,MATCH(E8,keycodes!$A:$A,0),0),INDEX(keycodes!$C:$C,MATCH(E8,keycodes!$A:$A,0),0)),INDEX(keycodes!$C:$C,MATCH(E8,keycodes!$B:$B,0),0))) -> _______ | F40: =IF(F8="",keycodes!$C$2,IF($B$1="Japanese",IF(INDEX(keycodes!$E:$E,MATCH(F8,keycodes!$A:$A,0),0)<>"",INDEX(keycodes!$E:$E,MATCH(F8,keycodes!$A:$A,0),0),INDEX(keycodes!$C:$C,MATCH(F8,keycodes!$A:$A,0),0)),INDEX(keycodes!$C:$C,MATCH(F8,keycodes!$B:$B,0),0))) -> _______ | G40: =IF(G8="",keycodes!$C$2,IF($B$1="Japanese",IF(INDEX(keycodes!$E:$E,MATCH(G8,keycodes!$A:$A,0),0)<>"",INDEX(keycodes!$E:$E,MATCH(G8,keycodes!$A:$A,0),0),INDEX(keycodes!$C:$C,MATCH(G8,keycodes!$A:$A,0),0)),INDEX(keycodes!$C:$C,MATCH(G8,keycodes!$B:$B,0),0))) -> _______ | H40: =IF(H8="",keycodes!$C$2,IF($B$1="Japanese",IF(INDEX(keycodes!$E:$E,MATCH(H8,keycodes!$A:$A,0),0)<>"",INDEX(keycodes!$E:$E,MATCH(H8,keycodes!$A:$A,0),0),INDEX(keycodes!$C:$C,MATCH(H8,keycodes!$A:$A,0),0)),INDEX(keycodes!$C:$C,MATCH(H8,keycodes!$B:$B,0),0))) -> NONE | I40: =IF(I8="",keycodes!$C$2,IF($B$1="Japanese",IF(INDEX(keycodes!$E:$E,MATCH(I8,keycodes!$A:$A,0),0)<>"",INDEX(keycodes!$E:$E,MATCH(I8,keycodes!$A:$A,0),0),INDEX(keycodes!$C:$C,MATCH(I8,keycodes!$A:$A,0),0)),INDEX(keycodes!$C:$C,MATCH(I8,keycodes!$B:$B,0),0))) -> NONE | ... O40: =IF(O8="",keycodes!$C$2,IF($B$1="Japanese",IF(INDEX(keycodes!$E:$E,MATCH(O8,keycodes!$A:$A,0),0)<>"",INDEX(keycodes!$E:$E,MATCH(O8,keycodes!$A:$A,0),0),INDEX(keycodes!$C:$C,MATCH(O8,keycodes!$A:$A,0),0)),INDEX(keycodes!$C:$C,MATCH(O8,keycodes!$B:$B,0),0))) -> _______
B41: =IF(B9="",keycodes!$C$2,IF($B$1="Japanese",IF(INDEX(keycodes!$E:$E,MATCH(B9,keycodes!$A:$A,0),0)<>"",INDEX(keycodes!$E:$E,MATCH(B9,keycodes!$A:$A,0),0),INDEX(keycodes!$C:$C,MATCH(B9,keycodes!$A:$A,0),0)),INDEX(keycodes!$C:$C,MATCH(B9,keycodes!$B:$B,0),0))) -> KC_APP | C41: =IF(C9="",keycodes!$C$2,IF($B$1="Japanese",IF(INDEX(keycodes!$E:$E,MATCH(C9,keycodes!$A:$A,0),0)<>"",INDEX(keycodes!$E:$E,MATCH(C9,keycodes!$A:$A,0),0),INDEX(keycodes!$C:$C,MATCH(C9,keycodes!$A:$A,0),0)),INDEX(keycodes!$C:$C,MATCH(C9,keycodes!$B:$B,0),0))) -> S(KC_1) | D41: =IF(D9="",keycodes!$C$2,IF($B$1="Japanese",IF(INDEX(keycodes!$E:$E,MATCH(D9,keycodes!$A:$A,0),0)<>"",INDEX(keycodes!$E:$E,MATCH(D9,keycodes!$A:$A,0),0),INDEX(keycodes!$C:$C,MATCH(D9,keycodes!$A:$A,0),0)),INDEX(keycodes!$C:$C,MATCH(D9,keycodes!$B:$B,0),0))) -> S(KC_2) | E41: =IF(E9="",keycodes!$C$2,IF($B$1="Japanese",IF(INDEX(keycodes!$E:$E,MATCH(E9,keycodes!$A:$A,0),0)<>"",INDEX(keycodes!$E:$E,MATCH(E9,keycodes!$A:$A,0),0),INDEX(keycodes!$C:$C,MATCH(E9,keycodes!$A:$A,0),0)),INDEX(keycodes!$C:$C,MATCH(E9,keycodes!$B:$B,0),0))) -> S(KC_3) | F41: =IF(F9="",keycodes!$C$2,IF($B$1="Japanese",IF(INDEX(keycodes!$E:$E,MATCH(F9,keycodes!$A:$A,0),0)<>"",INDEX(keycodes!$E:$E,MATCH(F9,keycodes!$A:$A,0),0),INDEX(keycodes!$C:$C,MATCH(F9,keycodes!$A:$A,0),0)),INDEX(keycodes!$C:$C,MATCH(F9,keycodes!$B:$B,0),0))) -> S(KC_4) | G41: =IF(G9="",keycodes!$C$2,IF($B$1="Japanese",IF(INDEX(keycodes!$E:$E,MATCH(G9,keycodes!$A:$A,0),0)<>"",INDEX(keycodes!$E:$E,MATCH(G9,keycodes!$A:$A,0),0),INDEX(keycodes!$C:$C,MATCH(G9,keycodes!$A:$A,0),0)),INDEX(keycodes!$C:$C,MATCH(G9,keycodes!$B:$B,0),0))) -> S(KC_5) | H41: =IF(H9="",keycodes!$C$2,IF($B$1="Japanese",IF(INDEX(keycodes!$E:$E,MATCH(H9,keycodes!$A:$A,0),0)<>"",INDEX(keycodes!$E:$E,MATCH(H9,keycodes!$A:$A,0),0),INDEX(keycodes!$C:$C,MATCH(H9,keycodes!$A:$A,0),0)),INDEX(keycodes!$C:$C,MATCH(H9,keycodes!$B:$B,0),0))) -> NONE | I41: =IF(I9="",keycodes!$C$2,IF($B$1="Japanese",IF(INDEX(keycodes!$E:$E,MATCH(I9,keycodes!$A:$A,0),0)<>"",INDEX(keycodes!$E:$E,MATCH(I9,keycodes!$A:$A,0),0),INDEX(keycodes!$C:$C,MATCH(I9,keycodes!$A:$A,0),0)),INDEX(keycodes!$C:$C,MATCH(I9,keycodes!$B:$B,0),0))) -> NONE | ... O41: =IF(O9="",keycodes!$C$2,IF($B$1="Japanese",IF(INDEX(keycodes!$E:$E,MATCH(O9,keycodes!$A:$A,0),0)<>"",INDEX(keycodes!$E:$E,MATCH(O9,keycodes!$A:$A,0),0),INDEX(keycodes!$C:$C,MATCH(O9,keycodes!$A:$A,0),0)),INDEX(keycodes!$C:$C,MATCH(O9,keycodes!$B:$B,0),0))) -> XXXXXXX
B42: =IF(B10="",keycodes!$C$2,IF($B$1="Japanese",IF(INDEX(keycodes!$E:$E,MATCH(B10,keycodes!$A:$A,0),0)<>"",INDEX(keycodes!$E:$E,MATCH(B10,keycodes!$A:$A,0),0),INDEX(keycodes!$C:$C,MATCH(B10,keycodes!$A:$A,0),0)),INDEX(keycodes!$C:$C,MATCH(B10,keycodes!$B:$B,0),0))) -> KC_LGUI | C42: =IF(C10="",keycodes!$C$2,IF($B$1="Japanese",IF(INDEX(keycodes!$E:$E,MATCH(C10,keycodes!$A:$A,0),0)<>"",INDEX(keycodes!$E:$E,MATCH(C10,keycodes!$A:$A,0),0),INDEX(keycodes!$C:$C,MATCH(C10,keycodes!$A:$A,0),0)),INDEX(keycodes!$C:$C,MATCH(C10,keycodes!$B:$B,0),0))) -> XXXXXXX | D42: =IF(D10="",keycodes!$C$2,IF($B$1="Japanese",IF(INDEX(keycodes!$E:$E,MATCH(D10,keycodes!$A:$A,0),0)<>"",INDEX(keycodes!$E:$E,MATCH(D10,keycodes!$A:$A,0),0),INDEX(keycodes!$C:$C,MATCH(D10,keycodes!$A:$A,0),0)),INDEX(keycodes!$C:$C,MATCH(D10,keycodes!$B:$B,0),0))) -> KC_HOME | E42: =IF(E10="",keycodes!$C$2,IF($B$1="Japanese",IF(INDEX(keycodes!$E:$E,MATCH(E10,keycodes!$A:$A,0),0)<>"",INDEX(keycodes!$E:$E,MATCH(E10,keycodes!$A:$A,0),0),INDEX(keycodes!$C:$C,MATCH(E10,keycodes!$A:$A,0),0)),INDEX(keycodes!$C:$C,MATCH(E10,keycodes!$B:$B,0),0))) -> KC_PGUP | F42: =IF(F10="",keycodes!$C$2,IF($B$1="Japanese",IF(INDEX(keycodes!$E:$E,MATCH(F10,keycodes!$A:$A,0),0)<>"",INDEX(keycodes!$E:$E,MATCH(F10,keycodes!$A:$A,0),0),INDEX(keycodes!$C:$C,MATCH(F10,keycodes!$A:$A,0),0)),INDEX(keycodes!$C:$C,MATCH(F10,keycodes!$B:$B,0),0))) -> KC_PGDN | G42: =IF(G10="",keycodes!$C$2,IF($B$1="Japanese",IF(INDEX(keycodes!$E:$E,MATCH(G10,keycodes!$A:$A,0),0)<>"",INDEX(keycodes!$E:$E,MATCH(G10,keycodes!$A:$A,0),0),INDEX(keycodes!$C:$C,MATCH(G10,keycodes!$A:$A,0),0)),INDEX(keycodes!$C:$C,MATCH(G10,keycodes!$B:$B,0),0))) -> KC_END | H42: =IF(H10="",keycodes!$C$2,IF($B$1="Japanese",IF(INDEX(keycodes!$E:$E,MATCH(H10,keycodes!$A:$A,0),0)<>"",INDEX(keycodes!$E:$E,MATCH(H10,keycodes!$A:$A,0),0),INDEX(keycodes!$C:$C,MATCH(H10,keycodes!$A:$A,0),0)),INDEX(keycodes!$C:$C,MATCH(H10,keycodes!$B:$B,0),0))) -> NONE | I42: =IF(I10="",keycodes!$C$2,IF($B$1="Japanese",IF(INDEX(keycodes!$E:$E,MATCH(I10,keycodes!$A:$A,0),0)<>"",INDEX(keycodes!$E:$E,MATCH(I10,keycodes!$A:$A,0),0),INDEX(keycodes!$C:$C,MATCH(I10,keycodes!$A:$A,0),0)),INDEX(keycodes!$C:$C,MATCH(I10,keycodes!$B:$B,0),0))) -> NONE | ... O42: =IF(O10="",keycodes!$C$2,IF($B$1="Japanese",IF(INDEX(keycodes!$E:$E,MATCH(O10,keycodes!$A:$A,0),0)<>"",INDEX(keycodes!$E:$E,MATCH(O10,keycodes!$A:$A,0),0),INDEX(keycodes!$C:$C,MATCH(O10,keycodes!$A:$A,0),0)),INDEX(keycodes!$C:$C,MATCH(O10,keycodes!$B:$B,0),0))) -> KC_MINS
B43: =IF(B11="",keycodes!$C$2,IF($B$1="Japanese",IF(INDEX(keycodes!$E:$E,MATCH(B11,keycodes!$A:$A,0),0)<>"",INDEX(keycodes!$E:$E,MATCH(B11,keycodes!$A:$A,0),0),INDEX(keycodes!$C:$C,MATCH(B11,keycodes!$A:$A,0),0)),INDEX(keycodes!$C:$C,MATCH(B11,keycodes!$B:$B,0),0))) -> _______ | C43: =IF(C11="",keycodes!$C$2,IF($B$1="Japanese",IF(INDEX(keycodes!$E:$E,MATCH(C11,keycodes!$A:$A,0),0)<>"",INDEX(keycodes!$E:$E,MATCH(C11,keycodes!$A:$A,0),0),INDEX(keycodes!$C:$C,MATCH(C11,keycodes!$A:$A,0),0)),INDEX(keycodes!$C:$C,MATCH(C11,keycodes!$B:$B,0),0))) -> KC_LALT | D43: =IF(D11="",keycodes!$C$2,IF($B$1="Japanese",IF(INDEX(keycodes!$E:$E,MATCH(D11,keycodes!$A:$A,0),0)<>"",INDEX(keycodes!$E:$E,MATCH(D11,keycodes!$A:$A,0),0),INDEX(keycodes!$C:$C,MATCH(D11,keycodes!$A:$A,0),0)),INDEX(keycodes!$C:$C,MATCH(D11,keycodes!$B:$B,0),0))) -> XXXXXXX | E43: =IF(E11="",keycodes!$C$2,IF($B$1="Japanese",IF(INDEX(keycodes!$E:$E,MATCH(E11,keycodes!$A:$A,0),0)<>"",INDEX(keycodes!$E:$E,MATCH(E11,keycodes!$A:$A,0),0),INDEX(keycodes!$C:$C,MATCH(E11,keycodes!$A:$A,0),0)),INDEX(keycodes!$C:$C,MATCH(E11,keycodes!$B:$B,0),0))) -> XXXXXXX | F43: =IF(F11="",keycodes!$C$2,IF($B$1="Japanese",IF(INDEX(keycodes!$E:$E,MATCH(F11,keycodes!$A:$A,0),0)<>"",INDEX(keycodes!$E:$E,MATCH(F11,keycodes!$A:$A,0),0),INDEX(keycodes!$C:$C,MATCH(F11,keycodes!$A:$A,0),0)),INDEX(keycodes!$C:$C,MATCH(F11,keycodes!$B:$B,0),0))) -> KC_INT5 | G43: =IF(G11="",keycodes!$C$2,IF($B$1="Japanese",IF(INDEX(keycodes!$E:$E,MATCH(G11,keycodes!$A:$A,0),0)<>"",INDEX(keycodes!$E:$E,MATCH(G11,keycodes!$A:$A,0),0),INDEX(keycodes!$C:$C,MATCH(G11,keycodes!$A:$A,0),0)),INDEX(keycodes!$C:$C,MATCH(G11,keycodes!$B:$B,0),0))) -> KC_BSPC | H43: =IF(H11="",keycodes!$C$2,IF($B$1="Japanese",IF(INDEX(keycodes!$E:$E,MATCH(H11,keycodes!$A:$A,0),0)<>"",INDEX(keycodes!$E:$E,MATCH(H11,keycodes!$A:$A,0),0),INDEX(keycodes!$C:$C,MATCH(H11,keycodes!$A:$A,0),0)),INDEX(keycodes!$C:$C,MATCH(H11,keycodes!$B:$B,0),0))) -> _______ | I43: =IF(I11="",keycodes!$C$2,IF($B$1="Japanese",IF(INDEX(keycodes!$E:$E,MATCH(I11,keycodes!$A:$A,0),0)<>"",INDEX(keycodes!$E:$E,MATCH(I11,keycodes!$A:$A,0),0),INDEX(keycodes!$C:$C,MATCH(I11,keycodes!$A:$A,0),0)),INDEX(keycodes!$C:$C,MATCH(I11,keycodes!$B:$B,0),0))) -> _______ | ... O43: =IF(O11="",keycodes!$C$2,IF($B$1="Japanese",IF(INDEX(keycodes!$E:$E,MATCH(O11,keycodes!$A:$A,0),0)<>"",INDEX(keycodes!$E:$E,MATCH(O11,keycodes!$A:$A,0),0),INDEX(keycodes!$C:$C,MATCH(O11,keycodes!$A:$A,0),0)),INDEX(keycodes!$C:$C,MATCH(O11,keycodes!$B:$B,0),0))) -> S(KC_INT3)
...
